Workbook

Sheet (ΒΑΘΜΟΛΟΓΙΕΣ 2026Α)
A1: ΠΑΠΑΔΟΠΟΥΛΟΣ ΑΝΤΩΝΙΟΣ | B1: ΕΡΓΑΣΙΑ 20% | C1: ΤΕΛΙΚΗ ΕΞΕΤΑΣΗ 80% | D1: ΤΕΛΙΚΟΣ ΒΑΘΜΟΣ | G1: ΕΣΩΤΕΡΙΚΗ ΑΡΧΙΚΤΕΚΤΟΝΙΚΗ ΔΙΑΚΟΣΜΗΣΗ ΚΑΙ ΣΧΕΔΙΑΣΜΟΣ ΑΝΤΙΚΕΙΜΕΝΩΝ ΕΤΟΣ
A2: ΑΝΑΓΕΝΝΗΣΗ ΚΑΙ ΝΕΟΤΕΡΗ ΤΕΧΝΗ | B2: 10 | C2: 9 | D2: 9
A3: ΔΙΣΔΙΑΣΤΑΤΗ ΨΗΦΙΑΚΗ ΣΧΕΔΙΑΣΗ | B3: 9 | C3: 10 | D3: 10
A4: ΔΟΜΙΚΑ ΣΤΟΙΧΕΙΑ ΕΣΩΤΕΡΙΚΩΝ ΧΩΡΩΝ | B4: 10 | C4: 8 | D4: 8
A5: ΜΕΘΟΔΟΛΟΓΙΑ ΜΕΛΕΤΗΣ ΔΙΑΚΟΣΜΗΣΗΣ | B5: 10 | C5: 8 | D5: 8
A6: ΠΑΡΑΓΩΓΑ ΥΛΙΚΑ | B6: 10 | C6: 10 | D6: 10
A7: ΠΡΑΚΤΙΚΗ ΕΦΑΡΜΟΓΗ ΣΕ ΧΩΡΟΥΣ ΚΑΤΟΙΚΙΑΣ | B7: 10 | C7: 9 | D7: 9
A8: ΤΡΙΣΔΙΑΣΤΑΤΗ ΔΙΑΚΟΣΜΗΤΙΚΗ | B8: 7 | C8: 9 | D8: 9
A10: ΑΝΑΣΤΑΣΙΑΔΗ ΝΙΚΟΛΕΤΑ | B10: ΕΡΓΑΣΙΑ 20% | C10: ΤΕΛΙΚΗ ΕΞΕΤΑΣΗ 80% | D10: ΤΕΛΙΚΟΣ ΒΑΘΜΟΣ
A11: ΑΝΑΓΕΝΝΗΣΗ ΚΑΙ ΝΕΟΤΕΡΗ ΤΕΧΝΗ | B11: 8 | C11: 8 | D11: 8
A12: ΔΙΣΔΙΑΣΤΑΤΗ ΨΗΦΙΑΚΗ ΣΧΕΔΙΑΣΗ | B12: 6 | C12: 10 | D12: 9
A13: ΔΟΜΙΚΑ ΣΤΟΙΧΕΙΑ ΕΣΩΤΕΡΙΚΩΝ ΧΩΡΩΝ | B13: 9 | C13: 10 | D13: 10
A14: ΜΕΘΟΔΟΛΟΓΙΑ ΜΕΛΕΤΗΣ ΔΙΑΚΟΣΜΗΣΗΣ | B14: 10 | C14: 10 | D14: 10
A15: ΠΑΡΑΓΩΓΑ ΥΛΙΚΑ | B15: 10 | C15: 9 | D15: 9
A16: ΠΡΑΚΤΙΚΗ ΕΦΑΡΜΟΓΗ ΣΕ ΧΩΡΟΥΣ ΚΑΤΟΙΚΙΑΣ | B16: 10 | C16: 9 | D16: 9
A17: ΤΡΙΣΔΙΑΣΤΑΤΗ ΔΙΑΚΟΣΜΗΤΙΚΗ | B17: 7 | C17: 8 | D17: 8
A19: ΚΟΥΤΣΟΓΙΑΝΝΑΚΗΣ ΙΩΑΝΝΗΣ | B19: ΕΡΓΑΣΙΑ 20% | C19: ΤΕΛΙΚΗ ΕΞΕΤΑΣΗ 80% | D19: ΤΕΛΙΚΟΣ ΒΑΘΜΟΣ
A20: ΑΝΑΓΕΝΝΗΣΗ ΚΑΙ ΝΕΟΤΕΡΗ ΤΕΧΝΗ | B20: 8 | C20: 6 | D20: 6
A21: ΔΙΣΔΙΑΣΤΑΤΗ ΨΗΦΙΑΚΗ ΣΧΕΔΙΑΣΗ | B21: 6 | C21: 8 | D21: 8
A22: ΔΟΜΙΚΑ ΣΤΟΙΧΕΙΑ ΕΣΩΤΕΡΙΚΩΝ ΧΩΡΩΝ | B22: 8 | C22: 9 | D22: 9
A23: ΜΕΘΟΔΟΛΟΓΙΑ ΜΕΛΕΤΗΣ ΔΙΑΚΟΣΜΗΣΗΣ | B23: 10 | C23: 9 | D23: 9
A24: ΠΑΡΑΓΩΓΑ ΥΛΙΚΑ | B24: 10 | C24: 7 | D24: 8
A25: ΠΡΑΚΤΙΚΗ ΕΦΑΡΜΟΓΗ ΣΕ ΧΩΡΟΥΣ ΚΑΤΟΙΚΙΑΣ | B25: 8 | C25: 7 | D25: 7
A26: ΤΡΙΣΔΙΑΣΤΑΤΗ ΔΙΑΚΟΣΜΗΤΙΚΗ | B26: 10 | C26: 7 | D26: 8
A28: ΠΕΡΗΦΑΝΟΥ ΕΙΡΗΝΗ | B28: ΕΡΓΑΣΙΑ 20% | C28: ΤΕΛΙΚΗ ΕΞΕΤΑΣΗ 80% | D28: ΤΕΛΙΚΟΣ ΒΑΘΜΟΣ
A29: ΑΝΑΓΕΝΝΗΣΗ ΚΑΙ ΝΕΟΤΕΡΗ ΤΕΧΝΗ | B29: 10 | C29: 9 | D29: 9
A30: ΔΙΣΔΙΑΣΤΑΤΗ ΨΗΦΙΑΚΗ ΣΧΕΔΙΑΣΗ | B30: 8 | C30: 10 | D30: 10
A31: ΔΟΜΙΚΑ ΣΤΟΙΧΕΙΑ ΕΣΩΤΕΡΙΚΩΝ ΧΩΡΩΝ | B31: 10 | C31: 10 | D31: 10
A32: ΜΕΘΟΔΟΛΟΓΙΑ ΜΕΛΕΤΗΣ ΔΙΑΚΟΣΜΗΣΗΣ | B32: 10 | C32: 10 | D32: 10
A33: ΠΑΡΑΓΩΓΑ ΥΛΙΚΑ | B33: 10 | C33: 10 | D33: 10
A34: ΠΡΑΚΤΙΚΗ ΕΦΑΡΜΟΓΗ ΣΕ ΧΩΡΟΥΣ ΚΑΤΟΙΚΙΑΣ | B34: 10 | C34: 10 | D34: 10
A35: ΤΡΙΣΔΙΑΣΤΑΤΗ ΔΙΑΚΟΣΜΗΤΙΚΗ | B35: 10 | C35: 10 | D35: 10
A38: ΧΑΪΝΑΚΗ ΕΥΑ | B38: ΕΡΓΑΣΙΑ 20% | C38: ΤΕΛΙΚΗ ΕΞΕΤΑΣΗ 80% | D38: ΤΕΛΙΚΟΣ ΒΑΘΜΟΣ
A39: ΑΝΑΓΕΝΝΗΣΗ ΚΑΙ ΝΕΟΤΕΡΗ ΤΕΧΝΗ | B39: 10 | C39: 10 | D39: 10
A40: ΔΙΣΔΙΑΣΤΑΤΗ ΨΗΦΙΑΚΗ ΣΧΕΔΙΑΣΗ | B40: 9 | C40: 10 | D40: 10
A41: ΔΟΜΙΚΑ ΣΤΟΙΧΕΙΑ ΕΣΩΤΕΡΙΚΩΝ ΧΩΡΩΝ | B41: 10 | C41: 10 | D41: 10
A42: ΜΕΘΟΔΟΛΟΓΙΑ ΜΕΛΕΤΗΣ ΔΙΑΚΟΣΜΗΣΗΣ | B42: 10 | C42: 10 | D42: 10
A43: ΠΑΡΑΓΩΓΑ ΥΛΙΚΑ | B43: 10 | C43: 10 | D43: 10
A44: ΠΡΑΚΤΙΚΗ ΕΦΑΡΜΟΓΗ ΣΕ ΧΩΡΟΥΣ ΚΑΤΟΙΚΙΑΣ | B44: 10 | C44: 9 | D44: 9
A45: ΤΡΙΣΔΙΑΣΤΑΤΗ ΔΙΑΚΟΣΜΗΤΙΚΗ | B45: 10 | C45: 8 | D45: 8
...

Sheet ΠΕΡΙΕΧΟΜΕΝΑ - ΕΞΗΓΗΣΗ EXCEL 
A1: ΑΡΙΘΜΟΣ ΦΥΛΛΟΥ | B1: ΟΝΟΜΑΣΙΑ | C1: ΠΕΡΙΓΡΑΦΗ
A2: - | B2: (ΟΝΟΜΑ ΦΥΛΛΟΥ) | C2: Οπουδήποτε (αρχή, μέση, τέλος) βρίσκεται ή βρίσκονται φύλλο ή φύλλα που δεν έχει ή έχουν χρώμμα και είναι μέσα σε εισαγωγικά, είναι πρόχειρο και δουλέυεται εκείνη την περιόδο για αυτό υπάρχει, για παράδειγμα (ΒΑΘΜΟΛΟΓΙΕΣ 2026Α). Μετά την ολοκλρήρωση της δουλείας του θα διαγραφεί εντελώς ή θα μετακινηθεί το περιεχόμενο του σε άλλο ήδη υπάρχον φύλλο.
A3: 1 | B3: ΠΕΡΙΕΧΟΜΕΝΑ - ΕΞΗΓΗΣΗ EXCEL | C3: Στο φύλλο περιέχονται πληροφορίες που είναι χρήσιμες για την κατανόηση του συγκεκριμένου excel αρχείου
A4: 2 | B4: ΟΔΗΓΙΕΣ ΕΡΓΑΣΙΑΣ | C4: Στο φύλλο ΟΔΗΓΙΕΣ ΕΡΓΑΣΙΑΣ υπάρχουν οδηγίες για ΛΑΖΑΡΟ(Αποθηκευτικός Χώρος), ΠΗΓΑΣΟ (Πληροφοριακό Σύστημα Υπουργείου) και ECLASS (Εκπαιδευτική Πλατφόρμα)
A5: 3 | B5: ΘΕΜΑΤΑ ΠΡΟΣ ΕΠΙΛΥΣΗ | C5: Στο φύλλο περιέχονται παρατηρήσεις που είτε δεν αφορούν το άτομο που τις λαμβάνει, είτε δεν είναι για άμεση διευθέτηση για να μην ξεχαστούν.
A6: 4 | B6: ΕΝΗΜΕΡΩΣΗ ΚΑΤΑΣΤΑΣΗΣ Κ.ΚΑΘΑΡΑΚΗ | C6: Στο φύλλο περιέχονταιι πληροφορίες για τις νέες εγγραφές και για τους υπάρχοντες σπουδαστές και χρησιμέυει για όταν μας ρωτάει ο κ.Καθαράκης να έχουμε σύντομα μια εικόνα και να τον ενημερώνουμε
A7: 5 | B7: ΕΚΔΗΛΩΣΕΙΣ ΕΝΔΙΑΦΕΡΟΝΤΟΣ | C7: Στο φύλλο περιέχονται πληροφορίες για τις εκδηλώσεις ενδιαφέροντος. Εχει και πινακάκι με τα στατιστικά και λεεί από που μάθανε για την ΙΣΑΕΚ κλπ. Περιέχει όλες τις εκδηλώσεις ενδιαφέροντος από 26/06/2025.
A8: 6 | B8: ΚΑΤΑΣΤΑΣΗ ΣΠΟΥΔΑ ΚΑΙ ΕΚΠΑΙΔ | C8: Στο φύλλο κατάσταση σπουδα και εκπαιδ, περιέχονται πληροφορίες όπως ποιοι είναι οι σπουδαστές ανά τμήμα και οι εκπαιδευτές γενικα στοιχεία τους και απουσιές. Επίσης περιλαμβάνονται στοιχεία και για τους απόφοιτους που έχουν τελειώσει, για να υπάρχουν συγκεντρωμένα όλα σε ένα φύλλο.
A9: 7 | B9: ECLASS | C9: Στο φύλλο eclass, περιέχονται πληροφορίες όπως οδηγίες για eclass, λογαριασμοί εκπαιδευτών και εκπαιδευομένων, οδηγίες για πρώτη σύνδεση, πεδίο για αντιγραφή κλπ
A10: 8 | B10: ΠΡΟΤΥΠΟ ΕΓΓΡΑΦΗΣ USER ECLASS | C10: Στο φύλλο ΠΡΟΤΥΠΟ ΕΓΓΡΑΦΗΣ USER ECLASS, υπάρχει περιεχόμενο που βοηθάει σε νέα εγγραφή χρήστη στο eclass
A11: 9 | B11: AMADEUS | C11: Στο φύλλο AMADEUS περιέχονται πληροφορίες για ότι αφορά το πρόγραμμα. πχ για λογαρισμούς κλπ
A12: 10 | B12: ΧΡΗΣΙΜΑ ΤΗΛΕΦΩΝΑ | C12: Στο φύλλο αυτό περιέχονται πληροφορίες για τα τηλέφωνα ΔΣ, μαστόρων, καθαριότητας κλπ
A13: 11 | B13: ΜΑΘΗΜΑΤΑ ΕΞΑΜΗΝΩΝ | C13: Στο φύλλο περιέονται πληροφορίες για τους καθηγητές και τα προσοντα που χρειάζεται να έχουν για το χειμερινό και εαρινό εξάμηνο για να προγραμματίσουμε ποιους θα έχουμε
A14: 12 | B14: ΑΠΟΥΣΙΕΣ ΕΞΑΜΗΝΩΝ | C14: Στο φύλλο περιέονται πληροφορίες για το όριο απουσιών που έχει το κάθε ένα μάθημα ανά εξάμηνο χειμερινό και εαρινό και αναρτάτε στα έγγραφα και στο eclass
... A22: 20 | B22: ΒΑΘΜΟΛΟΓΙΕΣ ΠΡΟΧΕΙΡΟ | C22: Το φύλλο ΒΑΘΜΟΛΟΓΙΕΣ ΠΡΟΧΕΙΡΟ χρησιμοποιείτε κάθε τέλος του εξαμήνου (χειμερινό και εαρινό). Καθώς το eclass, δεν έχει δυνατότητα να ανεβάσουμε βαθμολογίες. Έτσι περνάμε εκεί τις βαθμολογίες, βάζοντας φίλτρο και πατόντας το αντίστιχο μάθημα, θα βάλουμε τις βαθμολογίες και μετά θα το κάνουμε αντιγραφή και επικόληση ως εικόνα και θα τους το στείλουμε στο email

Sheet ΟΔΗΓΙΕΣ ΕΡΓΑΣΙΑΣ
A1: ΛΑΖΑΡΟΣ - (Αποθηκευτικός Χώρος)
A2: ΦΑΚΕΛΟΣ | B2: ΕΞΗΓΗΣΗ ΠΕΡΙΕΧΟΜΈΝΟΥ ΦΑΚΕΛΟΥ ΚΑΙ ΧΡΗΣΙΜΟΤΗΤΑ
A3: iek (\\192.168.2.79) | B3: Στον φάκελο, μπαίνεις στο δίπλα ονομα (iek (\\192.168.2.79))
A4: A_ΙΙΕΚ ΓΡΑΜΜΑΤΕΙΑ | B4: Για τα δικά μας θέματα ΙΕΚ, μπαίνουμε στο φάκελο με όνομα: A_ΙΙΕΚ ΓΡΑΜΜΑΤΕΙΑ
A5: ΕΓΓΡΑΦΑ ΓΙΑ ΕΝΗΜΕΡΩΣΕΙΣ | B5: Στο φάκελο "ΕΓΓΡΑΦΑ ΓΙΑ ΕΝΗΜΕΡΩΣΕΙΣ", υπάρχουν μέσα όλα τα αρχεία προς εκτύπωση για τα ραντεβού (ενημέρωση για ΙΣΑΕΚ και πραγματοποίηση εγγραφών). Επίσης υπάρχουν τα δίδακτρα και οι ΟΔΗΓΟΙ ΣΠΟΥΔΩΝ (προσοχοί υπάρχουν οι νεοι, τα άλλα είναι για αρχείο κλπ
A6: ΕΓΓΡΑΦΕΣ | B6: Στο φάκελο "ΕΓΓΡΑΦΕΣ", υπάρχουν μέσα υποφάκελοι με εγγραφές ανά έτος, στο 2026 όταν μπεις έχει ανα τμήμα τις εγγραφές και τα στοιχεία που μας έχουν φέρει και τα έχουμε σκανάρει
A7: ΕΚΠΑΙΔΕΥΤΕΣ | B7: Στο φάκελο "ΕΚΠΑΙΔΕΥΤΕΣ", υπάρχουν μέσα κάποια γενικά στοιχεία για τους εκπαιδευτές, τα υπόλοιπα συμβάσεις κλπ, υπάρχον στις συμβάσεις εκπαιδευτών ανα έτος.
A8: ΕΚΠΑΙΔΕΥΤΙΚΟ ΥΛΙΚΟ | B8: Στο φάκελο "ΕΚΠΑΙΔΕΥΤΙΚΟ ΥΛΙΚΟ", υπάρχουν μέσα οι σημειώσεις που έχουμε κάνει για τις ειδικότητες που έχουμε το ακαδημαικο έτος 2025Β-2026Α. Έχουμε και εκπαιδευτικό υλικό για κύριο Καθαράκη, διότι τα ήθελε αλλιώς αποθηκευμένα (είναι όμως οι ίδιες οι σημειώσεις)
A9: ΕΞΑΜΗΝΟ 2026Α | B9: Υπάρχουν διάφοροι φάκελοι που είναι με όνοματα εξαμήνων πχ ΕΞΑΜΗΝΟ 2026Α εκεί μέσα υπάρχουν όλα τα αρχεία που αφορούν το εξάμηνο πχ προγράμματα (εξαμήνου, εξετάσεων), θέματα εξετάσεων, αξιολογήσεις, συμβάσεις εκπαιδευτικών κλπ)
A10: ΣΤΟΙΧΕΙΑ ΣΠΟΥΔΑΣΤΩΝ | B10: Τα γενικά στοιχεία ΣΠΟΥΔΑΣΤΩΝ θα τα βρείς στις εγγραφές, ανάλογα με το έτος εγγραφής τους.
A11: ΣΤΟΙΧΕΙΑ ΕΚΠΑΙΔΕΥΤΕΣ | B11: Τα γενικά στοιχεία ΕΚΠΑΙΔΕΥΤΩΝ θα τα βρείς στο φάκελο εκπαιδευτές και οι συμβάσεις τους θα είναι στα επιμέρους εξάμηνα
A14: Πληροφοριακό Σύστημα του Υπουργείου - ΠΗΓΑΣΟΣ (https://pegasus.it.minedu.gov.gr/site/welcome)
A15: ΚΟΡΔΕΛΑ - ΕΠΙΛΟΓΗ | B15: ΕΞΗΓΗΣΗ - ΤΙ ΠΕΡΙΕΧΕΙ
A16: ΒΕΒΕΙΑΩΣΕΙΣ | B16: Αν κάποιος ζητήσει βεβαίωση (φοίτησης -σπουδών, στρατολογίας, ατομικό δελτίο - γράφει αναλυτικά και τα μαθήματα και τις βαθμολογίες τους αν θέλουν κλπ). Πάμε στο πληροφοριακό σύστημα του υπουργείου - ΠΗΓΑΣΟΣ (https://pegasus.it.minedu.gov.gr/site/welcome), πατάμε πάνω στην κορδέλα που γράφει βεβαιώσεις. Επιλέγουμε ποια βεβαιώση μας ζήτησαν, πχ βεβαίωση φοίτησης σπουδών (τα ζητάνε οι λογιστές τους συνήθως) και πατάμε αναζήτηση με όνομα ή επίθετο σπουδαστή. Έπειτα πατάμε το μπλέ έγγραφο στα δεξιά και βάζουμε αριθμό προτοκώλου από το πράσινο βιβλίο και επιλέγουμε ποιος θα υπογράψει πχ Μιχελάκη. Και πατάμε Δημιουργία, το εκτυπώνουμε, βάζουμε σφραγίδα και υπογραφή και το σκανάρουμε να το στείλουμε ή το στέλνουμε επι τόπου.
A20: ΠΡΑΚΤΙΚΗ - ΑΠΑΛΛΑΓΗ ΚΑΙ ΒΕΚ | B20: ΔΗΛΩΣΗ ΠΡΑΚΤΙΚΗΣ: Για να δηλωθεί πρακτική σε κάποιον, πάμε στον ΠΗΓΑΣΟ πατάμε εκεί που γράφει ΠΡΑΚΤΙΚΗ - ΜΑΘΗΤΕΙΑ, πατάμε έναρξη-απαλλαγή και μετά επιλέγουμε το έκαστοτε άτομο πχ μέσω αναζήτησης και μετά επιλέγεις το βαλιτσάκι = πρακτική ή το Α=απαλλαγή, έπειτα για πρακτική επιλέγεις εργοδότη (αναζητάς μέσω ΑΦΜ να δείς αν υπάρχει, αν δεν υπάρχει πατάς το βαλιτσάκι και βρίσκεις αποθηκεύεις ότι στοιχεία σου ζητάει) μετά πατάς επιλογή εργοδότη με το μπλε ξαπλωτό τρίγωνο και βάζεις ότι άλλα στοιχεία χρειάζονται και κάνεις επόμενο και έναρξη στιγμιοτύπου) μετά κάνεις έναρξη, βάζεις αριθμό πρωτοκόλου και τον κύριο Καθαράκη και πατάς έναρξη και βάζεις σφραγγίδα και του το πάς να υπογράψει. Για την απαλαγή πατάμε Α και έπειτα γράφουμε σχόλια πως έχει απασχοληθεί στην (....) επιχείρηση ή επιχειρήσεις και έχει συμπληρώσει 960 ώρες. Έπειτα στέλνουμε email, στην Κοτανίδι (ekotanidi@minedu.gov.gr), με ΘΕΜΑ: ΑΠΑΛΛΑΓΗ ΠΡΑΚΤΙΚΗΣ + ΟΝΟΜΑΤΕΠΩΝΥΜΟ ΣΠΟΥΔΑΣΤΗ και με KEIMENO: Καλημέρα κ. Κοτανίδη. Σας επισυνάπτω τα δικαιολογητικά για την απόφοιτη .......... με ΑΜ ..... από την ειδικότητα .................., προκειμένου να εγκρίνετε την ολική απαλλαγή λόγω προϋπηρεσίας. Έχει ανοιχτεί στιγμιότυπο απαλλαγής 960 ωρών. Σας ευχαριστώ πολύ εκ των προτέρων.. Στο emailεπισυνάπτεις: 1. Βεβαίωση Προυπηρεσίας, 2. Ένσημα και 3. Υπέυθυνη Δήλωση μέσω gov που γράφει: " έχω συμπληρώσει τα 120 ένσημα 8ωρης απασχόλησης στην επιχείρηση.............. ή στις επιχειρήσεις ............. με την ειδικότητα βοηθός μάγειρα ή γ΄ μάγειρα ή ζαχαροπλάστη και αιτούμαι την ολική απαλλαγή από την πρακτική άσκηση της ειδικότητάς μου.......................". (συμπληρώνετε τα κενά ανάλογα την ειδικότητα που έχει ο καθένας σας και τους εργοδότες που εργάστηκε), (τα έγγραφα αυτά τα 3 τα ζητάμε και μας τα έχει στείλει ο σπουδαστής). Μετά όταν έχει δει τα έγγραφα και τα έχει τσεκάρει η Κοτανίδη θα κάνει έγκριση και εσύ θα το δείς από τον ΠΗΓΑΣΟ εκεί που λεεί Διαχείρηση Πρακτικής - Μαθητείας εκεί θα γράφει πως θα το δείχνει πράσινο και μετά θα πατάς το τικ και αν έχει τελειώσει πατάς ΒΕΚ ---> Έκδοση ΒΕΚ ---> επιλέγεις τον σπουδαστή και γράφεις από το καφέ - γαλάζιο Βιβλίο Πρακτικών αριθμό πράξης τον τελευταίο αριθμό στα αριστερά, ημερομηνία και αριθμό ΒΕΚ που θα είναι ο επόμενος από αυτόν που βλέπεις πχ είναι 17 θα βάλεις 18 και μετά θα πατήσεις έκδοση. Η ΒΕΚ εκτυπώνεται σε κάτι κίτρινα διαφορετικά από το κανονικό χαρτί, τα οποία είναι κάτω στα ντουλάπάκια δίπλα στον εκτυπωτή και το βάζεις και ανοίγεις τα άλλα ράφια, για να εκτυπωθεί σε αυτό και βάζεις και σφραγγίδα και υπογραφή από Καθαράκη και όταν έρθει κάνει βάζεις την φωτογραφία (τύπου ταυτότητας) πάνω και το εκτυπώνεις να το βάλεις στο φάκελο με τις ΒΕΚ και το σκανάρεις και το βάζεις και στο ΛΑΖΑΡΟ --> ΙΕΚ ΓΡΑΜΜΑΤΕΙΑ-->ΒΕΚ
A31: ΛΕΙΤΟΥΡΓΙΕΣ | B31: Οτιδήποτε πρόβλημα ή απορία έχεις με τον ΠΗΓΑΣΟ, πχ καθηστερεί η ΒΕΚ να εγκριθεί είτε μιλάς με την ΕΠΟΠΤΡΙΑ αν αυτό είναι στο δικό της χέρι όπως η έγκριση, είτε στέλνεις στην υπηρεσία μηνυμάτων, πας Λετουργίες ---> Υπηρεσίες Μηνυμάτων --> Πατάς το πράσινο κυκλάκι με τον φάκελο και μετά γράφεις το αίτημα σου είτε στην ΤΕΧΝΙΚΗ ΥΠΟΣΤΗΡΙΞΗ αν το θέμα είναι κάτι με το σύστημα (πχ δεν μπορώ να βγάλω βεβαίωση σπουδών σε ένα μαθητή, δεν μου εμφανίζει την δυνατότητα), είτε το θέμα είναι διαχειριστικό Ιπχ δεν ξέρω ποιος υπογράφει για να εκτυπωθεί η ΒΕΚ που δεν έχει επικυρωθεί ακόμα) και εκείνοι σου απαντάνε και σε καθοδηγούνε.
A35: ΙΣΑΕΚ ΕΠΙΜΕΛΗΤΗ | B35: Εκεί που γράφει ΙΣΑΕΚ ΕΠΙΜΕΛΗΤΗ κάνουμε προγράμματα, ωρολόγια κλπ
A39: ΚΑΤΑΡΤΙΣΗ | B39: Στο ΚΑΤΑΡΤΙΣΗ θα βρείς ότι είναι σχετικό με τους σπουδαστές. Στο ΜΗΤΡΩΟ ΚΑΤΑΡΤΙΖΟΜΕΝΩΝ που εκεί είναι όλοι μας οι σπουδαστές και τα στοιχεία τους. Εκεί επίσης περγάνε τις νέες εγγραφές, μετεγραφές κλπ στα αντίστοιχα πεδία. Βάζουμε τις απουσίες, βαθμολογίες κλπ.
A43: ΑΝΑΦΟΡΕΣ | B43: Τις αναφορές τις χρησιμοποιούμε στο τέλος του εξαμήνου που κλείνουμε το εκάστοτε εξάμηνο
A47: Πλατφόρμα Εκπαίδευσης ECLASS (https://eclass-isaek.katartisi.gr/)
A48: ΕΠΙΛΟΓΕΣ | B48: ΕΞΗΓΗΣΗ
A49: #VALUE! | B49: Στο γενικό περιβάλλον θα βλέπεις μαθήματα κλπ. Θα βάλεις την γραμματεία στα αγαπημένα - αστέρι την ΓΡΑΜΜΑΤΕΙΑ που είναι όλη η ενημέρωση που κάνουμε εμείς ως γραμματεία.
A53: ΔΗΜΙΟΥΡΓΙΑ ΜΑΘΗΜΑΤΩΝ | B53: Αν το τμήμα δεν είναι καινούργιο και δεν έχουν δημιουργηθεί μαθήματα κάνεις τα παρακάτω βήματα. 1. Πατάς πάνω στην εικόνα σου (πάνω δεξιά), 2. Πατάς την 2η επιλογή που γράφει Δημιουργία Μαθήματος. 3. Συμπληρώνεις Τίτλο Μαθήματος πχ Παράγωγα Υλικά, κωδικό δεν βάζεις, στην κατηγορία επιλέγεις ΙΣΑΕΚ Επιμελητηρίου Ηρακλείου μετά επιλέγεις τομέα και τμήμα, στο πεδίο εκπαιδευτές βάζεις αν ξέρεις αλλιώς αφήνεις το δικό σου όνομα και το αλλάζεις όταν μάθεις εκπαιδευτή, εικόνα δεν βάζεις (βάζει ο εκπαιδευτής) εκτός αν έχουμε διαφορετική οδηγία, στην μορφή το αφήνεις το προεπιλεγμένο που είναι ΜΟΡΦΗ ΜΕ ΕΝΟΤΗΤΕΣ, στην άδεια χρήσης βάζουμε την τελευταία επιλογή που λέει "Άδεια χρήσης Creative Commons (CC)", στο πεδίο Διαθέσιμοι τύποι πρόσβασης βάζουμε ανοιχτό και μετά Δημιουργία μαθήματος και έχει δημιουργηθεί. Για να το δεις ξανά επιλέγεις πάνω πάνω αριστερά που έχει το σήμα της ΙΣΑΕΚ και πάς στην αρχική, πατάς την επιλογή Διαχείρηση Πλατφόρμας που είναι δεξιά κάτω από την αναζήτηση, έπειτα επιλέγουμε στο κέντρο που γράφει μαθήματα, μετά αναζήτηση μαθημάτων, πατάς τον μεγενθυτικό φακό δεξιά που γράφει όλα τα μαθήματα, αναζητάς με τίτλο, και το βρίσκεις και πατάς πάνω στο όνομα και το βλέπεις και για να αλλάξεις πράγματα πχ το όνομα του εκπαιδευτή, εκεί που είσαι μέσα στο μάθημα πατάς πάνω δεξιά Διαχείρηση Μαθήματος, ρυθμίσεις και αλλάζεις τα στοιχεία. και πατάς υποβολή.
A64: ΔΗΜΙΟΥΡΓΙΑ ΧΡΗΣΤΗ/ΣΤΩΝ | B64: Για να δημιουργήσεις χρήστες στο eclass μαζικά ή μεμονομένα (1. ΠΗΓΑΙΝΟΥΜΕ ΣΤΟ ΦΥΛΛΟ ΔΕΞΙΑ ΠΡΟΤΥΠΟ ΕΓΓΡΑΦΗ USER ECLASS , ΓΡΑΦΟΥΜΕ ΌΛΑ ΤΑ ΣΤΟΙΧΕΙΑ ΠΟΥ ΘΕΛΟΥΜΕ(ΚΑΛΟ ΘΑ ΗΤΑΝ ΝΑ ΠΕΡΝΟΥΝΤΑΙ ΜΑΘΗΤΕΣ Ή ΚΑΘΗΓΗΤΕΣ ΑΝΑ ΤΜΗΜΑ) ΝΑ ΒΑΛΟΥΜΕ, 2. ΜΕΤΑ ΠΗΓΑΙΝΟΥΜΕ ECLASS ΔΙΑΧΕΙΡΗΣΗ ΠΛΑΤΦΟΡΜΑΣ ΠΑΝΩ ΔΕΞΙΑ, 3. ΜΑΖΙΚΗ ΔΗΜΙΟΥΡΓΙΑ ΛΟΓΑΡΙΑΣΜΩΝ ΧΡΗΣΤΩΝ (ΑΝΕΞΑΡΤΗΤΑ ΑΝ Ο ΜΑΘΗΤΗΣ Ή ΚΑΘΗΓΗΤΗΣ ΕΙΝΑΙ ΕΝΑΣ), 4. ΚΑΝΟΥΜΕ ΔΕΞΙ ΚΛΙΚ ΠΑΝΩ ΣΤΟ ΦΥΛΛΟ ΠΡΟΤΥΠΟ ΓΙΑ ΕΓΓΡΑΦΗ (ΔΙΠΛΑ ΣΤΟ ΦΥΛΛΟ ECLASS) ΚΑΙ ΕΠΙΛΕΓΟΥΜΕ ΜΕΤΑΚΙΝΗΣΗ Ή ΑΝΤΙΓΡΑΦΗ, ΜΕΤΑ ΚΑΝΟΥΜΕ ΚΛΙΚ ΣΤΟ ΠΕΔΙΟ ΑΝΤΙΓΡΑΦΗ ΚΑΙ ΚΑΝΟΥΜΕ ΣΕ ΆΛΛΟ ΒΙΒΛΙΟ ΚΑΙ ΤΟ ΚΑΙΝΟΥΡΓΙΟ ΒΙΒΛΙΟ ΟΠΩΣ ΕΙΝΑΙ ΤΟ ΑΠΟΘΗΚΕΥΟΥΜΕ ΣΤΙΣ ΛΗΨΕΙΣ ΜΕ ΟΝΟΜΑ ΟΠΩΣ ΘΕΛΟΥΜΕ ΕΙΤΕ ΒΙΒΛΙΟ ΕΊΤΕ ΟΤΙ ΘΕΛΟΥΜΕ ΠΧ ΟΝΟΜΑ ΜΑΘΗΤΗ, 5. ΕΠΕΙΤΑ ΑΝΕΒΑΖΟΥΜΕ ΤΟ ΑΡΧΕΙΟ ΚΑΙ ΕΠΙΛΕΓΟΥΜΕ ΕΙΔΟΣ ΛΟΓΑΡΙΣΜΟΥ ΠΧ ΕΚΠΑΙΔΕΥΟΜΕΝΟΣ, ΚΛΙΚΑΡΟΥΜΕ ΣΤΗΝ ΑΛΛΑΓΗ ΣΥΝΘΗΜΑΤΙΚΟΥ ΚΑΤΑ ΤΗΝ ΕΙΣΟΔΟ, ΣΤΗΝ ΚΑΤΗΓΟΡΙΑ ΕΠΙΛΕΓΟΥΜΕ ΤΟ ΤΜΗΜΑ ΤΟΥ, ΤΑ ΑΛΛΑ ΔΕΝ ΤΑ ΠΕΙΡΑΖΟΥΜΕ ΚΑΙ ΜΕΤΑ ΚΛΙΚΑΡΟΥΜΕ ΚΑΙ ΤΟ ΑΠΟΣΤΟΛΗ ΤΩΝ ΣΤΟΙΧΕΙΩΝ ΤΟΥ ΜΕΣΩ EMAIL 6. ΤΕΛΟΣ ΤΟ ΚΑΝΟΥΜΕ ΥΠΟΒΟΛΗ)
A68: ΕΓΓΡΑΦΗ ΧΡΗΣΤΩΝ ΣΕ ΜΑΘΗΜΑΤΑ | B68: Για να εγγράψεις χρήστες ακολουθείς τα παρακάτω βήματα 1. Πάμε στο αρχείο eclass (στο οποίο έχουμε καταγράψει όλους τους μαθητές τα ονόματα τους και όλους τους καθηγητές και όλα τα μαθήματα - καλό θα είναι να ανανεώνεται κάθε φορά που έχουμε κάτι καινούργιο), 2. Στο eclass πάμε κάτω από την αναζήτηση τέρμα δεξιά και πατάμε Διαχείρηση Πλατφόρμας, μετά κάτω αριστερά εκεί που γράφει Χρήστες, επιλέγουμε το Μαζική εγραφή χρηστών σε μαθήματα (που είναι 3η επιλογή από το τέλος), 3. Γράφουμε τα username μαθητών ή καθηγητών και τους κωδικούς μαθημάτων που τους βρήσκουμε από το αρχείο ECLASS, (αν κάποιος κωδικός μαθήματος δεν υπάρχει μπορούμε εύκολα να τον βρούμε από την αρχική σελίδα δίπλα στο όνομα του μαθήματος) επιλέγουμε ρόλο, δηλασή αν αυτός/αυτοί που γράφουμε είναι εκπαιδευτές/μαθητές κλπ και το βάζουμε. (Υ.Γ. Στους εκπαιδεύτες καλό θα ήταν να βάζουμε ρόλο Διαχειριστής - Εκπαιδευτής, έτσι ώστε να έχουν περισσότερες δυνατότητες στα μαθήματα τους) και πατάμε εγγραφή. Αν θέλουμε να δούμε τους χρήστες του κάθε μαθήματος, πάμε ξανά στην αρχική πατώντας το logo της ΙΣΑΕΚ πάνω αριστερά και μετά επιλέγουμε το εκάστοτε μάθημα με αριστερο κλικ πάνω στο τίτλο μαθήματος, αν θέλω να δώ χρήστες πατάω τα 3 ανθρωπάκια που είναι δίπλα στο γρανάζι και κάτω από τον τίτλο, βλέπουμε τους εγγεγραμμένους. Αν έχουμε κάνει κάποιο λάθος πχ ένα εκπαιδεύομενο τον βάλαμε εκπαιδευτή, πατάμε το γρανάζι δίπλα στο όνομα του και αλλάζουμε την ιδιότητα αν θέλουμε να αφαιρέσουμε κάποιον πατάμε το κόκκινο με το Χ.

Sheet ΘΕΜΑΤΑ ΠΡΟΣ ΕΠΙΛΥΣΗ
A1: ΗΜΕΡΟΜΗΝΙΑ | B1: ΠΑΡΑΤΗΡΗΣΕΙΣ- ΣΧΟΛΙΑ | C1: ΤΙ ΑΦΟΡΆ | D1: ΠΟΙΟΝ ΑΦΟΡΟΥΝ | F1: ΕΞΗΓΗΣΗ ΧΡΩΜΑΤΩΝ
A2: 45757 | B2: Οι σπουδαστές ανάφεραν να έχει ο αυτόματος πολιτής καφέ και σόδα με λεμόνι και άλλα τσάγια για τώρα που ζεστένει ο καιρός | C2: ΤΡΟΦΟΔΟΣΙΑ | D2: Μαίρη | F2: ΔΕΝ ΕΧΕΙ ΛΥΘΕΙ ΑΚΟΜΑ
A3: 45758 | B3: Να βγάζουν οι επιμελητές μια φωτογραφία κάθε εργαστηριακό μάθημα και να ανεβαίνει μια φωτοφραφία στα social media από το τι κάνει το ΙΣΑΕΚ | C3: Social Media | D3: Μαρία + Σοφία Επιμελήτριες | F3: OK έχει γίνει
A4: 45758 | B4: Οι σπουδαστές κ. Μαρκάκη Τρυπάκη Πελαγία έχουν παράπονο πως τα θέματα είναι πολύ συμπτιγμένα και δεν μπορούν να τα δούνε καθαρά για να απαντήσουν | C4: ΕΞΕΤΑΣΕΙΣ | D4: κ.Καθαράκης & Μέλπω (να τα κάνουμε πιο αραιά ) | F4: ΠΡΟΤΑΣΕΙΣ ΓΙΑ ΒΕΛΤΙΩΣΗ
A5: 45761 | B5: Η κυρία Μπίτζου θέλει οι αναρτήσεις στα social media να γίνονται όπως ακριβώς τις στέλνει και να μην είναι παιδιάστικες διότι υπονομέυουν το αντικείμενο | C5: ΠΡΟΩΘΗΣΗ | D5: κ.Καθαράκης | F5: ΕΊΝΑΙ ΖΗΤΗΜΑΤΑ ΤΑ ΟΠΟΙΑ ΕΊΝΑΙ ΔΙΑΔΙΚΑΣΤΙΚΑ ΚΑΙ ΓΡΑΦΕΙ ΟΔΗΓΙΕΣ ΠΩΣ ΛΥΝΟΝΤΑΙ
A6: 45761 | B6: Η κυρία Μπίτζου θέλει να μάθει τι έγινε με την κ. Ζαχαριαδάκη για να έχει χρόνο τώρα το Πάσχα εκείνη και η άλλη καθηγήτρια κ. Σκόρδου να προετοιμάσουν υλικό, ανάλογα με το τι συμφωνήθηκε | C6: ΕΚΠΑΙΔΕΥΤΕΣ | D6: κ.Καθαράκης
A7: 45761 | B7: Η κυρία Μπίτζου θέλει να δούμε μαζί με την Μέλπω το πρόγραμμα για να κανονιστει | C7: ΠΡΟΓΡΑΜΜΑ | D7: Μέλπω
A8: 45761 | B8: Ενημερώνουμε την κ. Ζαχαριαδάκη πως θα προσπαθήσουμε να διατηρίσουμε το πρόγραμμα για τα μαθήματα που παραμένουν σε εκείνη ως έχει και αν υπάρξει επείγουσα ανάγκη να αλλάξει κάτι, θα την ενημερώσουμε τις επόμενες μέρες | C8: ΠΡΟΓΡΑΜΜΑ | D8: Κατερίνα
A9: 45761 | B9: Κάλεσε η κυρία Αντωνακάκη Ελένη για να μάθει για Ζαχαριαδάκη επειδή έλειπε την προυγούμενη εβδομάδα | C9: ΣΠΟΥΔΑΣΤΕΣ | D9: Μέλπω
A10: 45761 | B10: Ο κύριος Καθαράκης ανέφερε να κοιτάξουμε ξανά για το mentoring για Linkedln και να προγραμματιστούν συναντίσεις με τον κ. Καθαράκη ή εμάς για την σταδιοδρομία και την δημιουργία βιογραφικού | C10: ΣΠΟΥΔΑΣΤΕΣ | D10: Μέλπω
A11: 45761 | B11: Ο κύριος Καθαράκης ανέφερε να δούμε για δράσεις που θα συμμετέχουν οι σπουδαστές και θα ενισχύσει το βιογραφικό τους | C11: ΔΡΑΣΕΙΣ | D11: Μέλπω
A12: 45761 | B12: Ο κύριος Καθαράκης ανέφερε να ελεγξώ social media τα δικά μας για απόδοση | C12: Social Media | D12: Κατερίνα
A13: 45761 | B13: Μας κάλεσε κ. Ζωιτού που έχει λογιστικό γραφείο καθώς ενδιαφέρετε για πρακτικάριους. Το γραφείο της είναι Εθνικής Αντιστάσεως και το τηλέφωνο 2810330472 | C13: ΠΡΑΚΤΙΚΗ | D13: κ.Καθαράκης & Μέλπω
A14: 45762 | B14: Με κάλέσε η κυρία Καλογεράκη Σύλβια 6937318064 από το αεροδρόμιο για την πρακτικη της Σμυρνάκης Κωνσταντίνας και θέλει τα δικαιολογητικά, για να δεί πως θα πληρώνεται η κυρία, να ξεκινήσει κλπ. Της έχει στείλει λεει και η Μέλπω email με κάποια στοιχεία (ωράριο και διαθεσιμότητες) | C14: ΠΡΑΚΤΙΚΗ | D14: Μέλπω
A15: 45762 | B15: Γιώργο Βλαχάκη τον πειράζει να γινεί το μάθημα αντί Δεύτερα να γίνει Παρασκευή | C15: ΣΠΟΥΔΑΣΤΕΣ | D15: Κατερίνα
A16: 45762 | B16: Βιογραφικό Αρχιτεκτόνων που ενδιαφέρονται για Εκπαιδευτές να σταλούν στην κ.Μπιτζού | C16: ΕΚΠΑΙΔΕΥΤΕΣ | D16: Μέλπω
A17: 45762 | B17: Πρόοδους Ζαχαριαδάκη για τα μαθήματα που δεν θα κάνει πλέων. Ποιος θα τα κάνει | C17: ΕΚΠΑΙΔΕΥΤΕΣ | D17: Μέλπω
... A65: 45798 | B65: Να συζητήσουμε άυριο με την Μέλπω για τα θέματα ΠΗΓΑΣΟΣ που δεν αποτυπώνει σωστά τις ώρες που γίνονται πχ ΠΕΤΡΟΥΛΑΚΗ που δεν έκανε εχτές. Και θέμα με κυρία Αμπαρτζάκη που τις δηλώνουμε τις ώρες μια φορά μόνο και όχι κάθε φορά που δεν κάνει μάθημα κάποιος και κάνει αλλού αναπλήρωση και ώρες πχ ΑΔΑΜΗ που δεν κάνει κάποιες και τις δηλώνουμε στον ΠΗΓΑΣΟ. Επίσης να δούμε το θέμα με τον ΤΙΤΛΟ ΚΤΗΣΗΣ που δεν πρέπει να κόβουμε από εκεί τα χρήματα. Να συζητήσουμε για τις απουσίες των παιδιών που νομίζουν πως δεν θα μήνουν | C65: ΔΙΑΔΙΚΑΣΙΕΣ | D65: κύριος Καθαράκης, Μέλπω
A66: 09:30 Γκριτζάς δικηγορος | B66: ΠΛΥΜΜΗΡΑ | C66: Τηλέφωνο | D66: Μέλπω
A67: 45799 | B67: Να ζητήσουμε από τους εκπαιδευτές, ΠΡΑΚΤΙΚΗ ΑΣΚΗΣΗ-διακοσμιση Β ΕΤΟΣ, ΑΕΡΟΠΟΡΙΚΟΙ ΝΑΥΛΟΙ - ΑΕΡΟΜΕΤΑΦΟΡΑ ΕΠΑΝΑΚΗ | C67: ΠΡΟΟΔΟΣ | D67: Κατερίνα, Μέλπω
A68: 45799 | B68: ΕΡΩΤΗΜΑΤΑ ΑΠΌ ΑΡΧΙΤΕΚΤΟΝΕΣ Β ΣΑΚΟΥΛΑΚΗ ΓΙΑ ΠΡΑΚΤΙΚΗ ΑΝ ΕΧΕΙ ΠΡΟΚΥΡΙΞΗ ΓΙΑ ΝΑ ΠΑΡΕΙ ΕΠΙΔΟΤΗΣΗ ΤΩΡΑ ΚΑΙ ΚΟΥΚΟΥΛΑΚΗ ΓΙΑ ΤΟ ΤΑΞΙΔΙ ΑΝ ΘΑ ΜΠΟΡΕΣΕΙ ΝΑ ΠΑΕΙ ΕΠΕΙΔΗ ΔΕΝ ΦΑΙΝΕΤΑΙ ΚΑΤΑΓΕΓΡΑΜΕΝΗ ΣΤΟ ΣΥΣΤΗΜΑ ΚΑΙ ΠΑΡΑΚΟΛΟΥΘΕΙ ΩΣ ΣΕΜΙΝΑΡΙΟ | C68: ΠΡΑΚΤΙΚΗ | D68: Κατερίνα, Μέλπω
A69: 45799 | B69: Να πώ στους αρχιτέκτονες, να στείλουν email στην Ηλέκτρα για να δούνε τα θέματα | C69: ΕΚΔΡΟΜΗ | D69: Κατερίνα
A70: 45803 | B70: Να δώσω στον Κυρλάκη να υπογράψει την σύμβαση του | C70: ΕΚΠΑΙΔΕΥΤΕΣ | D70: Κατερίνα
A71: 45804 | B71: Να ρωτήσω την Μέλπω αν θέλει να εκτυπώσουμε τις εργασίες που μας έστειλε η Πέλα από τα παιδία ή αρκεί να είναι στον φάκελο διαδικτυακά | C71: ΕΚΠΑΙΔΕΥΤΕΣ | D71: Μέλπω
A72: 45806 | B72: 6955581674 ΣΗΦΑΚΗ ΑΡΧΙΤΕΚΤΟΝΙΚΟ ΓΡΑΦΕΙΟ, ΣΤΕΡΓΟΓΙΑΝΝΗ 60 | C72: ΠΡΑΚΤΙΚΗ | D72: Μέλπω
A73: 45806 | B73: Οι αρχιτέκτονες β έτος θέλουν να κάνουν και εκείνοι τα σεμινάρια από οκτώμβριο δωρεάν. Όπως είχαμε πει στην Μαρίνα | C73: ΣΕΜΙΝΑΡΙΟ | D73: Κ.Καθαράκης, Μέλπω
A74: 45806 | B74: Η Ζαχαριαδάκη, πάλι απειλούσε πως θα μας κάνει μήνυμση, έχει φωτογραφίες με τις απουσίες των φοιτητών και θα κάνει λεει καταγγελία πως δεν έχουν μεινει. Είπε πως δεν ξέρω πως τα σκέυτεσεται μερικοί (κ.Καθαράκης) και κάνετε ότι σας πουνε οι σπουδαστές και ότι αυτή πάει πάντα by the book και δεν θέλει να κάνει λήξει εξεαμήνου αυτή την εβδομάδα (ανέφερε και για τα χρήματα και της είπα πως δεν θα κοπούν τα χρήματα και πως θα είναι μέσα και οι εξετάσεις και δεν ήθελε, της είπα αν θέλει να τους κάνει μάθημα και μετά την εξεταστική ως κάτι έξτρα και πάλι δεν ήθελε οπότε θα γράψουν σε εκείνη μετά της 10/06 | C74: ΕΚΠΑΙΔΕΥΤΕΣ | D74: Κ.Καθαράκης, Μέλπω
A75: 45807 | B75: Να ρωτήσω για κάρτες για να βγάλουμε για εμάς τους καινούργιους και ότι και όσα λείβονται τους άλλους | C75: ΚΑΡΤΕΣ | D75: Κ.Καθαράκης, Μέλπω
A76: 45807 | B76: Οι Μαρία Αστρινάκη και Γεωργία Σακουλάκη, Σμαραγδάκης Χριστόφορος, θέλουν πρακτική στην Σηφάκη | C76: ΠΡΑΚΤΙΚΗ | D76: Μέλπω
A77: 45807 | B77: Να δούμε για την Πέλα, ποια μαθήματα μπορεί να κάνει για του χρόνου μέχρι Παρασκευή 06/05/2025 για να κανονίσει το πρόγραμμα της | C77: ΕΚΠΑΙΔΕΥΤΕΣ | D77: Μέλπω | E77: ΠΡΑΚΤΙΚΗ ΕΦΑΡΜΟΓΗ ΣΤΗΝ ΕΙΔΙΚΟΤΗΤΑ 3 ΩΡΕΣ, ΔΙΟΙΚΗΣΗ ΑΕΡΟΔΡΟΜΙΩΝ ΚΑΙ ΑΕΡΟΠΟΡΙΚΩΝ ΕΤΑΙΡΕΙΩΝ 2 ΩΡΕΣ, ΛΕΙΤΟΥΡΓΙΕΣ ΕΤΑΙΡΕΙΩΝ ΕΠΙΓΕΙΑΣ ΕΞΥΠΗΡΕΤΗΣΗ 2 ΩΡΕΣ, ΔΙΑΧΕΙΡΗΣΗ ΚΡΙΣΕΩΝ ΚΑΙ ΑΠΩΛΕΙΑΣ ΑΠΟΣΚΕΥΩΝ 2 ΩΡΕΣ
A78: 45807 | B78: Να δούμε το βιβλίο ύλης να το συμπληρώσουν όλοι μέχρι το τέλος γιατί μου είπε η Πέλα ότι τα κοιτάνε | C78: ΕΚΠΑΙΔΕΥΤΕΣ | D78: Μέλπω
A79: 45807 | B79: Σαλουθροστ Ελευθερία μας την συστησε ο Βλαχάκης και θα ερθει Δευτέρα 02/06/2025 στις 18:00. Τηλέφωνο: 6945932104 | C79: ΣΥΝΑΝΤΗΣΗ | D79: Μέλπω, Κατερίνα
A80: 45810 | B80: Να ρωτήσω την κυρία Σκόρδου για τα θέματα | C80: ΕΚΠΑΙΔΕΥΤΕΣ | D80: Κατερίνα
A81: 45810 | B81: Να ετοιμάσουμε τα στοιχεία και να τα στείλουμε στο Κώστα για τα βιογραφικά | C81: ΣΠΟΥΔΑΣΤΕΣ | D81: Κατερίνα
A82: 45811 | B82: Να δούμε αν η Μαρίνα Σιτορέγκο μπορεί να πάρει απαλαγή επειδή διδασκέ μόδα | C82: ΠΡΑΚΤΙΚΗ | D82: Μέλπω | E82: Να μας φέρει επίσημο έγγραφο από το GOV για μη μισθωτούς
A83: 45811 | B83: Να κοιτάξω τις διαφορές που υπάρχουν στις ώρες που έστειλε η λογίστρια και τις δικές μας και από που προκύπτουν | C83: ΕΚΠΑΙΔΕΥΤΕΣ | D83: Κατερίνα
A84: 45812 | B84: Να δώσουμε στην τελετη αποφοίτησης σε 50 ΑΤΟΜΑ να είναι σε Α3 φυλλάδιο και να το δίνουμε στο folder της σχολής (πιο χοντρο εξώφυλλο, αφαίρεση πλαισίου) (οικολογικο ή απλό χαρτί λίγο πιο χοντρό από το χαρτί του εκτυπωτή) | C84: ΕΚΠΑΙΔΕΥΤΕΣ | D84: Μέλπω, Κατερίνα
A85: 45812 | B85: Να ρωτήαω για ώρες τον κύριο Τσικαλάκη την Παρασκευή για τις ώρες του κύριου Κουμάκη | C85: ΕΚΠΑΙΔΕΥΤΕΣ | D85: Κατερίνα
A86: 45813 | B86: Να συζητήσουμε για την Αργυρώ Σταμπουλή που θέλει να φύγει από του χρόνου. Αλλά δεν είναι γιατι δεν υπάρχει οργάνωση, έχει λεει δικά της θέματα. Μας κοροιδευει όλο το τμήμα ότι ενημερώνουμε τελευταία στιγμή και οτί δεν είναι οργανωμένα… | C86: ΣΠΟΥΔΑΣΤΕΣ | D86: κύριος Καθαράκης, Μέλπω
A87: 45814 | B87: Να δώσω τις πολλές πληρωμές στην Νατάσα, της Παρασκευής | C87: ΣΠΟΥΔΑΣΤΕΣ | D87: Κατερίνα
...

Sheet ΕΝΗΜΕΡΩΣΗ ΚΑΤΑΣΤΑΣΗΣ Κ.ΚΑΘΑΡΑΚΗ
A1: ΤΜΗΜΑ | B1: ΑΡΙΘΜΟΣ ΕΓΓΡΑΦΩΝ | C1: ΕΓΓΡΑΦΕΣ ΓΙΑ 2ο ΈΤΟΣ
A2: ΕΣΩΤΕΡΙΚΗ ΑΡΧΙΤΕΚΤΟΝΙΚΗ ΔΙΑΚΟΣΜΙΣΗ ΚΑΙ ΣΧΕΔΙΑΣΜΟΣ ΑΝΤΙΚΕΙΜΕΝΩΝ | B2: =COUNT('ΚΑΤΑΣΤΑΣΗ ΣΠΟΥΔΑ ΚΑΙ ΕΚΠΑΙΔ'!G2:G12) -> 0 | C2: 0
A3: ΣΤΕΛΕΧΟΣ ΔΙΟΙΚΗΣΗΣ ΚΑΙ ΟΙΚΟΝΟΜΙΑΣ | B3: =COUNT('ΚΑΤΑΣΤΑΣΗ ΣΠΟΥΔΑ ΚΑΙ ΕΚΠΑΙΔ'!G22:G31) -> 0 | C3: 0
A4: ΤΕΧΝΙΚΟΣ ΑΡΤΟΠΟΙΙΑΣ ΚΑΙ ΖΑΧΑΡΟΠΛΑΣΤΙΚΗΣ | B4: =COUNT('ΚΑΤΑΣΤΑΣΗ ΣΠΟΥΔΑ ΚΑΙ ΕΚΠΑΙΔ'!G68:G77) -> 0 | C4: 0
A5: ΣΤΕΛΕΧΟΣ ΥΠΗΡΕΣΙΩΝ ΑΕΡΟΜΕΤΑΦΟΡΑΣ | B5: =COUNT('ΚΑΤΑΣΤΑΣΗ ΣΠΟΥΔΑ ΚΑΙ ΕΚΠΑΙΔ'!G44:G54) -> 1 | C5: 0
A6: ΤΕΧΝΙΚΟΣ ΜΑΓΕΙΡΙΚΗΣ ΤΕΧΝΗΣ - ΑΡΧΙΜΑΓΕΙΡΑΣ ΣΕΦ | B6: =COUNT('ΚΑΤΑΣΤΑΣΗ ΣΠΟΥΔΑ ΚΑΙ ΕΚΠΑΙΔ'!G91:'ΚΑΤΑΣΤΑΣΗ ΣΠΟΥΔΑ ΚΑΙ ΕΚΠΑΙΔ'!G100) -> 2 | C6: 0
A7: ΥΠΟΛΟΓΙΣΤΩΝ | B7: =COUNT('ΚΑΤΑΣΤΑΣΗ ΣΠΟΥΔΑ ΚΑΙ ΕΚΠΑΙΔ'!G113:G120) -> 0 | C7: 0
A8: ΤΟΥΡΙΣΜΟΥ | B8: =COUNT('ΚΑΤΑΣΤΑΣΗ ΣΠΟΥΔΑ ΚΑΙ ΕΚΠΑΙΔ'!G123:G130) -> 0 | C8: 0
A9: ΣΥΝΟΛΟ | B9: =SUM(B2:B6) -> 3 | C9: =SUM(C2:C8) -> 0
A11: ΣΥΝΟΛΙΚΟ ΠΙΝΑΚΑΚΙ ΓΙΑ ΣΠΟΥΔΑΣΤΕΣ
A12: ΕΓΓΡΑΦΕΣ | B12: ΣΠΟΥΔΑΣΤΕΣ | C12: ΣΥΝΟΛΟ
A13: =SUM(B2:C8) -> 3 | B13: 29 | C13: =A13+B13 -> 32

Sheet ΕΚΔΗΛΩΣΕΙΣ ΕΝΔΙΑΦΕΡΟΝΤΟΣ
A1: Α/Α | B1: ΗΜΕΡΟΜΗΝΙΑ | C1: ΩΡΑ | D1: ΕΙΔΙΚΟΤΗΤΑ | E1: ΟΝΟΜΑΤΕΠΩΝΥΜΟ | F1: EMAIL | G1: ΤΗΛΕΦΩΝΟ | H1: ΑΠΌ ΠΟΥ ΜΑΘΑΤΕ ΓΙΑ ΤΗΝ ΙΣΑΕΚ | I1: ΣΧΟΛΙΑ
A2: 1 | B2: Πέμπτη, 26 Ιουνίου 2025 | C2: 0.57013889 | D2: Στέλεχος Δημοσίων Σχέσεων και Επικοινωνίας | E2: Αγγελική Σταματάκη | F2: aggelikistam1@gmail.com | G2: 6980020116 | H2: Απο φίλο / γνωστό | J2: ΣΥΝΟΛΟ | K2: ΕΙΔΙΚΟΤΗΤΑ | L2: ΑΡΙΘΜΟΣ ΕΝΔΙΑΦΕΡΟΜΕΝΩΝ
A3: 2 | B3: Δευτέρα, 30 Ιουνίου 2025 | C3: 0.59444444 | D3: Τεχνικός Λογισμικού Ηλεκτρονικών Υπολογιστών | E3: ΝΙΚΟΣ ΓΙΩΡΓΑΚΗΣ | F3: nikosgiorgakis343@gmail.com | G3: 6943802760 | H3: Απο φίλο / γνωστό | J3: =COUNT(C2:C258) -> 63 | K3: Εσωτερική Αρχιτεκτονική Διακόσμηση και Σχεδιασμός Αντικειμένων | L3: =COUNTIF(Πίνακας2[ΕΙΔΙΚΟΤΗΤΑ],"Εσωτερική Αρχιτεκτονική Διακόσμηση και Σχεδιασμός αντικειμένων") -> 30
A4: 3 | B4: Δευτέρα, 30 Ιουνίου 2025 | C4: 0.53611111 | D4: Εσωτερική Αρχιτεκτονική Διακόσμηση και Σχεδιασμός Αντικειμένων | E4: Iwona Kirzanowska | F4: iwona55@windowslive.com | G4: 6951957501 | H4: Ιστοσελίδα / Αναζήτηση | K4: Στέλεχος Δημοσίων Σχέσεων και Επικοινωνίας | L4: =COUNTIF(Πίνακας2[ΕΙΔΙΚΟΤΗΤΑ],"Στέλεχος Δημοσίων Σχέσεων και Επικοινωνίας") -> 4
A5: 4 | B5: Παρασκεύη, 04 Ιουλίου 2025 | C5: 0.088888889 | D5: Στέλεχος Μονάδων Φιλοξενίας | E5: Ελένη Καλογεράκη | F5: elenikalogeraki2005@gmail.com | G5: 6940880624 | H5: Ιστοσελίδα / Αναζήτηση
A6: 5 | B6: Τρίτη, 08 Ιουλίου 2025 | C6: 0.48819444 | D6: Εσωτερική Αρχιτεκτονική Διακόσμηση και Σχεδιασμός Αντικειμένων | E6: Σοφία Γιαχνακη | F6: so.giachnaki@gmail.com | G6: 6942996527 | H6: Ιστοσελίδα / Αναζήτηση | K6: Από που μάθανε για ΙΣΑΕΚ
A7: 6 | B7: Τρίτη, 08 Ιουλίου 2025 | C7: 0.56388889 | D7: Στέλεχος Διοίκησης και Οικονομίας | E7: NIKOLAOS KLEIDONIARIS | F7: nicklido21@gmail.com | G7: 6932422976 | H7: E-mail | K7: Email | L7: =COUNTIF(Πίνακας2[ΑΠΌ ΠΟΥ ΜΑΘΑΤΕ ΓΙΑ ΤΗΝ ΙΣΑΕΚ],"E-mail") -> 11 | M7: =L7/$J$3 -> 0.17460317
A8: 7 | B8: Τρίτη, 08 Ιουλίου 20265 | C8: 0.66041667 | D8: Εσωτερική Αρχιτεκτονική Διακόσμηση και Σχεδιασμός Αντικειμένων | E8: Ερη Βρουβακη | F8: erivrouvaki@gmail.com | G8: 6940097540 | H8: E-mail | K8: Facebook / Instagram | L8: =COUNTIF(Πίνακας2[ΑΠΌ ΠΟΥ ΜΑΘΑΤΕ ΓΙΑ ΤΗΝ ΙΣΑΕΚ],"Facebook / Instagram") -> 14 | M8: =L8/$J$3 -> 0.22222222
A9: 8 | B9: Τετάρτη, 09 Ιουλίου 20266 | C9: 0.51458333 | D9: Εσωτερική Αρχιτεκτονική Διακόσμηση και Σχεδιασμός Αντικειμένων | E9: Γεωργία Μπινιχάκη | F9: mpigeorgia@hotmail.com | G9: 6977731248 | H9: E-mail | K9: Από φίλο / γνωστό | L9: =COUNTIF(Πίνακας2[ΑΠΌ ΠΟΥ ΜΑΘΑΤΕ ΓΙΑ ΤΗΝ ΙΣΑΕΚ],"Απο φίλο / γνωστό") -> 19 | M9: =L9/$J$3 -> 0.3015873
A10: 9 | B10: Πέμπτη, 10 Ιουλίου 2025 | C10: 0.9625 | D10: Εσωτερική Αρχιτεκτονική Διακόσμηση και Σχεδιασμός Αντικειμένων | E10: Ανδριανα Καψαλη | F10: adrianakapsali@gmail.com | G10: 6949922242 | H10: Ιστοσελίδα / Αναζήτηση | K10: Ιστοσελίδα / Αναζήτηση | L10: =COUNTIF(Πίνακας2[ΑΠΌ ΠΟΥ ΜΑΘΑΤΕ ΓΙΑ ΤΗΝ ΙΣΑΕΚ],"Ιστοσελίδα / Αναζήτηση") -> 55 | M10: =L10/$J$3 -> 0.87301587 | N10: 1η
A11: 10 | B11: Σάββατο, 12 Ιουλίου 2025 | C11: 0.37013889 | D11: Στέλεχος Εμπορίας, Διαφήμισης και Προώθησης Προϊόντων (MARKETING) | E11: Eυα Πεσιου | F11: e_pesiou@yahoo.gr | G11: 6940167550 | H11: Ιστοσελίδα / Αναζήτηση | K11: Τηλεώραση | L11: =COUNTIF(Πίνακας2[ΑΠΌ ΠΟΥ ΜΑΘΑΤΕ ΓΙΑ ΤΗΝ ΙΣΑΕΚ],"Τηλεώραση") -> 0 | M11: =L11/$J$3 -> 0
A12: 11 | B12: Σάββατο, 12 Ιουλίου 2025 | C12: 0.37013889 | D12: Στέλεχος Μηχανογραφημένου Λογιστηρίου – Φοροτεχνικού Γραφείου | E12: Eυα Πεσιου | F12: e_pesiou@yahoo.gr | G12: 6940167550 | H12: Τηλεόραση
A13: 12 | B13: Σάββατο, 12 Ιουλίου 2025 | C13: 0.37083333 | D13: Στέλεχος Δημοσίων Σχέσεων και Επικοινωνίας | E13: Eυα Πεσιου | F13: e_pesiou@yahoo.gr | G13: 6940167550 | H13: Τηλεόραση
A14: 13 | B14: Τρίτη, 22 Ιουλίου 2025 | C14: 0.088888889 | D14: Στέλεχος Υπηρεσιών Αερομεταφοράς | E14: Παναγιώτα Μαυρογιαννάκη | F14: maraki_name@yahoo.gr | G14: 6945672911 | H14: Facebook / Instagram
A15: 14 | B15: Παρασκεύη, 25 Ιουλίου 2025 | C15: 0.99027778 | D15: Τεχνικός Μαγειρικής Τέχνης–Αρχιμάγειρας(CHEF) | E15: Κώστας Αγγελακης | F15: kostesangelakes@gmail.com | G15: 6976620640 | H15: Ιστοσελίδα / Αναζήτηση
A16: 15 | B16: Σάββατο, 26 Ιουλίου 2025 | C16: 0.25625 | D16: Στέλεχος διοίκησης και Οικονομίας στον Τομέα του Τουρισμού | E16: ΑΛΈΞΑΝΔΡΟΣ ΤΖΑΝΆΚΗΣ | F16: a.tzanakis@hotmail.com | G16: 6955957705 | H16: Facebook / Instagram
A17: 16 | B17: Σάββατο, 26 Ιουλίου 2025 | C17: 0.47430556 | D17: Εσωτερική Αρχιτεκτονική Διακόσμηση και Σχεδιασμός Αντικειμένων | E17: ΒΑΣΙΛΙΚΗ ΦΑΡΣΑΡΗ | F17: mzarmpa@gmail.com | G17: 6974246296 | H17: Απο φίλο / γνωστό
A18: 17 | B18: Δευτέρα, 28 Ιουλίου 2025 | C18: 0.55763889 | D18: Τεχνικός Αρτοποιίας – Ζαχαροπλαστικής | E18: Μελινα Αντωνάκη | F18: melinaantonaki@gmail.com | G18: 6972937741 | H18: E-mail
A19: 18 | B19: Δευτέρα, 28 Ιουλίου 2025 | C19: 0.55833333 | D19: Τεχνικός Αρτοποιίας – Ζαχαροπλαστικής | E19: Καμπιτάκη Ελένη | F19: mpap313@gmail.com | G19: 6938855788 | H19: E-mail
A20: 19 | B20: Δευτέρα, 28 Ιουλίου 2025 | C20: 0.55833333 | D20: Τεχνικός Αρτοποιίας – Ζαχαροπλαστικής | E20: ΔΕΣΠΟΙΝΑ ΚΑΛΑΙΤΖΑΚΗ | F20: d.kalaitzaki@gmail.com | G20: 6946681521 | H20: E-mail
A21: 20 | B21: Δευτέρα, 28 Ιουλίου 2025 | C21: 0.57361111 | D21: Εσωτερική Αρχιτεκτονική Διακόσμηση και Σχεδιασμός Αντικειμένων | E21: ΙΩΑΝΝΗΣ ΣΚΑΡΑΚΗΣ | F21: skarasrnr@gmail.com | G21: 6973334093 | H21: E-mail
A22: 21 | B22: Τρίτη, 29 Ιουλίου 2025 | C22: 0.52638889 | D22: Τεχνικός Μαγειρικής Τέχνης–Αρχιμάγειρας(CHEF) | E22: Δημήτρης Στυλιαράς | F22: styliaras11@gmail.com | G22: 6947290911 | H22: Απο φίλο / γνωστό
A23: 22 | B23: Τετάρτη, 30 Ιουλίου 2025 | C23: 0.70208333 | D23: Στέλεχος διοίκησης και οικονομίας στον τομέα του τουρισμού | E23: Αλισα Γιαρος | F23: vassillissa82@gmail.com | G23: 6930130198 | H23: Ιστοσελίδα / Αναζήτηση
... A28: 27 | B28: Δευτέρα, 04 Αυγούστου 2025 | C28: 0.68333333 | D28: Στέλεχος Μηχανογραφημένου Λογιστηρίου – Φοροτεχνικού Γραφείου | E28: Ελευθερια Ακουμιανακη | F28: eriakoumm@gmail.com | G28: 6942692585 | H28: Facebook / Instagram
A29: 28 | B29: Παρασκεύη, 08 Αυγούστου 2025 | C29: 0.88680556 | D29: Εσωτερική Αρχιτεκτονική Διακόσμηση και Σχεδιασμός Αντικειμένων | E29: Ιωάννης Μπορμπαντωνακης | F29: gianbormp@outlook.com.gr | G29: 6979009801 | H29: Ιστοσελίδα / Αναζήτηση | I29: ΤΗΝ ΚΑΛΕΣΑ ΖΗΤΟΥΣΕ ΠΛΗΡΟΦΟΡΙΕΣ ΓΙΑ ΑΝ ΕΙΜΑΣΤΕ ΔΗΜΟΣΑ Η ΙΔΙΩΤΙΚΗ ΣΧΟΛΗ, ΤΙ ΠΤΥΧΙΟ ΠΑΙΡΝΕΙ, ΤΟ ΚΟΣΤΟΣ ΚΑΙ ΕΙΠΕ ΘΑ ΜΙΛΗΣΕΙ ΜΕ ΤΟ ΠΑΙΔΙ ΤΗΣ ΚΑΙ ΘΑ ΜΑΣ ΕΝΗΜΕΡΩΣΕΙ
A30: 29 | B30: Σάββατο, 09 Αυγούστου 2025 | C30: 0.96805556 | D30: Τεχνικός Αρτοποιίας – Ζαχαροπλαστικής | E30: Μαρία Παπαδάκη | F30: mariapap1990@hotmail.com | G30: 6984816562 | H30: E-mail | I30: ΤΗΝ ΚΑΛΕΣΑ ΚΑΙ ΘΕΛΕΙ ΜΟΝΟ ΠΡΩΙΝΟ ΤΜΗΜΑ ΓΙΑΤΙ ΓΙΑ ΑΠΟΓΕΥΜΑ ΔΕΝ ΜΠΟΡΕΙ ΔΟΥΛΕΥΕΙ
A31: 30 | B31: Τρίτη, 12 Αυγούστου 2025 | C31: 0.38888889 | D31: Τεχνικός Μαγειρικής Τέχνης–Αρχιμάγειρας(CHEF) | E31: ΜΑΡΙΟΣ ΧΑΛΚΙΑΔΑΚΗΣ | F31: chalkiadakismarios@gmail.com | G31: 6974001347 | H31: Ιστοσελίδα / Αναζήτηση | I31: ΗΘΕΛΕ ΠΛΗΡΟΦΟΡΙΕΣ ΑΝ ΕΙΜΑΣΤΕ ΚΡΑΤΙΚΗ - ΔΗΜΟΣΙΑ ΑΠΌ ΌΤΙ ΚΑΤΑΛΑΒΑ ΣΧΟΛΗ ΚΑΙ ΘΕΛΕΙ ΚΑΠΟΙΑ ΣΤΙΓΜΗ ΝΑ ΕΡΘΕΙ ΝΑ ΜΑΘΕΙ ΠΕΡΙΣΣΟΤΕΡΕΣ ΠΛΗΡΟΦΟΡΙΕΣ ΕΠΕΙΔΗ ΛΕΕΙ ΔΟΥΛΕΥΕΙ ΤΟ ΠΑΙΔΙ ΘΑ ΕΡΘΕΙ ΚΑΠΟΙΑ ΣΤΙΓΜΗ Η ΜΑΝΑ ΝΑ ΜΑΘΕΙ Τις ΠΛΗΡΟΦΟΡΙΕΣ ΕΚΕΙΝΗ ΛΕΕΙ ΕΚΑΝΕ ΚΑΙ ΤΗΝ ΑΙΤΗΣΗ
A32: 31 | B32: Τετάρτη, 13 Αυγούστου 2025 | C32: 0.10138889 | D32: Τεχνικός Αρτοποιίας – Ζαχαροπλαστικής | E32: ΕΛΕΝΗ ΠΕΤΡΑΚΗ | F32: eleni1345@gmail.com | G32: 6975776225 | H32: Facebook / Instagram
A33: 32 | B33: Τετάρτη, 13 Αυγούστου 2025 | C33: 21:19 μμ | D33: Στέλεχος Υπηρεσιών Αερομεταφοράς | E33: ΧΡΥΣΗ ΧΟΧΛΙΔΑΚΗ | F33: xoxxry@yahoo.gr | G33: 6945327573 | H33: E-mail | I33: ΗΘΕΛΕ ΠΛΗΡΟΦΟΡΙΕΣ ΑΛΛΑ ΘΑ ΚΑΛΕΣΕΙ ΕΚΕΙΝΗ ΛΕΕΙ ΓΙΑ ΡΑΝΤΕΒΟΥ
A34: 33 | B34: Πέμπτη, 14 Αυγούστου 2025 | C34: 12:15 πμ | D34: Εσωτερική Αρχιτεκτονική Διακόσμηση και Σχεδιασμός Αντικειμένων | E34: MARIA VASILEIADOU | F34: mariavassiliadou38@gmail.com | G34: 6984656954 | H34: Facebook / Instagram | I34: ΗΘΕΛΕ ΠΙΟ ΠΟΛΎ ΓΙΑ ΤΟ ΜΑΘΗΜΑ ΙΣΤΟΡΙΑ ΤΕΧΝΗΣ ΚΑΙ ΤΗΣ ΕΣΤΕΙΛΑ ΟΔΗΓΟ ΣΠΟΥΔΩΝ. ΡΩΤΟΥΣΕ ΑΝ ΗΤΑΝ ΕΞ ΑΠΟΣΤΑΣΕΩΣ ΡΩΤΟΥΣΕ ΑΝ ΕΙΑΝΙ ΜΕΤΑΠΤΥΧΙΑΚΟ ΚΑΙ ΘΕΛΕΙ ΝΑ ΕΧΕΙΣ ΠΑΡΕΙ ΠΤΥΧΙΟ, ΤΗΣ ΤΑ ΕΞΗΓΗΣΑ ΚΑΙ ΕΙΠΕ ΘΑ ΚΑΛΕΣΕΙ ΔΕΥΤΕΡΑ ΓΙΑ ΝΑ ΚΛΕΙΣΕΙ ΡΑΝΤΕΒΟΥ ΑΝ ΔΕΝ ΚΑΛΕΣΕΙ ΘΑ ΚΑΛΕΣΩ ΠΑΡΑΣΚΕΥΗ
A35: 34 | B35: Παρασκεύη, 15 Αυγούστου 2025 | C35: 20:47 μμ | D35: Tεχνικός υπολογιστικών συστημάτων | E35: ΕΙΡΗΝΗ ΓΑΛΑΤΣΑΝΟΥ | F35: irenegaga9@gmail.com | I35: ΤΗΣ ΕΣΤΕΙΛΑ EMAIL, ΔΙΟΤΙ ΣΥΜΠΛΗΡΩΣΕ ΑΠΛΗ ΦΟΡΜΑ ΕΠΙΚΟΙΝΩΝΙΑΣ ΠΟΥ ΈΔΕΙΝΕ ΜΟΝΟ ΤΟ EMAIL ΚΑΙ ΌΧΙ ΤΟ ΤΗΛΕΦΩΝΟ ΓΙΑ ΝΑ ΤΗΝ ΚΑΛΕΣΩ ΚΑΙ ΤΙΣ ΑΠΑΝΤΗΣΑ ΣΤΑ ΕΡΩΤΗΜΑΤΑ
A36: 35 | B36: Παρασκεύη, 15 Αυγούστου 2025 | C36: 21:11 μμ | D36: Στέλεχος Υπηρεσιών Αερομεταφοράς | E36: Δέσποινα Πρασανάκη | F36: desppras@gmail.com | G36: 6980882454 | H36: Απο φίλο / γνωστό | I36: ΤΗΝ ΚΑΛΕΣΑ ΔΕΝ ΤΟ ΠΡΟΛΑΒΕ ΚΑΙ ΜΕ ΚΑΛΕΣΕ ΕΚΕΙΝΗ. ΗΘΕΛΕ ΠΛΗΡΟΦΟΡΙΕΣ ΓΙΑ ΤΗΝ ΦΟΙΤΗΣΗ ΑΝ ΕΊΝΑΙ 2 ΕΤΗ, ΠΟΙΕΣ ΩΡΕΣ ΘΑ ΓΙΝΟΝΤΑΙ ΤΑ ΜΑΘΗΜΑΤΑ, ΑΝ ΘΑ ΕΊΝΑΙ ΕΞ ΑΠΟΣΤΑΣΕΩΝ Ή ΔΙΑ ΖΩΣΗΣ ΚΑΙ ΠΟΣΑ ΕΊΝΑΙ ΤΑ ΧΡΗΜΑΤΑ ΠΟΥ ΘΑ ΠΛΗΡΩΣΕΙ ΚΑΙ ΕΙΠΕ ΘΑ ΔΕΙ ΤΟ ΠΡΟΓΡΑΜΜΑ ΤΗΣ ΚΑΙ ΘΑ ΜΕ ΚΑΛΕΣΕΙ ΝΑ ΚΛΕΙΣΟΥΜΕ ΡΑΝΤΕΒΟΥ
A37: 36 | B37: Τρίτη, 19 Αυγούστου 2025 | C37: 21:22 μμ | D37: Στέλεχος Μονάδων Φιλοξενίας | E37: Στεργιωτη Μιχελουδακη | F37: steriotimich76@gmail.com | G37: 6942279233 | H37: Facebook / Instagram | I37: ΗΘΕΛΕ ΓΙΑ ΔΙΟΙΚΗΣΗ ΚΑΙ ΟΙΚΟΝΟΜΙΑ ΣΤΟΝ ΤΟΜΕΑ ΤΟΥΡΙΣΜΟΥ,. ΕΊΝΑΙ ΠΡΟΙΣΤΑΜΕΝΗ ΟΡΟΦΩΝ ΚΑΙ ΤΗΝ ΕΝΔΙΕΦΕΡΕ ΠΕΡΙΣΣΟΤΕΡΟ ΟΡΟΦΟΚΟΜΙΑ ΚΛΠ ΚΑΙ ΜΕ ΡΩΤΗΣΕ ΓΙΑ ΔΙΔΑΚΤΡΑ ΚΛΠ ΩΡΕΣ ΑΝ ΕΊΝΑΙ ΕΞ ΑΠΟΣΤΑΣΕΩΣ ΚΑΙ ΗΘΕΛΕ ΝΑ ΜΑΘΕΙ ΜΑΘΗΜΑΤΑ ΓΙΑ ΤΟΥΡΙΣΜΟ ΚΑΙ ΑΝΑΛΥΤΙΚΑ ΤΙ ΕΧΕΙ ΚΑΙ ΤΗΣ ΕΣΤΕΙΛΑ ΣΤΟ EMAIL ΟΔΗΓΟ ΣΠΟΥΔΩΝ ΚΑΙ ΘΑ ΤΑ ΕΒΛΕΠΕ ΚΑΙ ΘΑ ΜΕ ΚΑΛΟΥΣΕ ΛΕΕΙ
A38: 37 | B38: Πέμπτη, 21 Αυγούστου 2025 | C38: 0.18819444 | D38: Στέλεχος Διοίκησης και Οικονομίας | E38: Μαρινα Κακουλακη | F38: kakoulakimarina00@gmail.com | G38: 6936594668 | H38: Facebook / Instagram | I38: ΤΗΝ ΚΑΛΕΣΑ ΚΑΙ ΔΕΝ ΤΟ ΑΠΑΝΤΗΣΕ ΚΑΙ ΤΗΣ ΕΣΤΕΙΛΑ EMAIL
A39: 38 | B39: Παρασκεύη, 22 Αυγούστου 2025 | C39: 13:30 μμ | D39: Στέλεχος Δημοσίων Σχέσεων και Επικοινωνίας | E39: ΕΙΡΗΝΗ ΦΑΝΟΥΡΑΚΗ | F39: eirinifc@hotmail.gr | G39: 6946303456 | H39: Ιστοσελίδα / Αναζήτηση | I39: ΤΗΝ ΚΑΛΕΣΑ ΚΑΙ ΗΘΕΛΕ ΠΛΗΡΟΦΟΡΙΕΣ ΓΙΑ ΤΑ ΧΡΗΜΑΤΑ ΑΡΧΙΚΑ. ΜΕ ΡΩΤΟΥΣΕ ΑΝ ΕΙΜΑΣΤΕ ΔΗΜΟΣΙΟ Η ΙΔΙΟΤΙΚΟ, ΞΙΝΕΣΕ ΚΑΙ ΕΙΠΕ ΚΑΙ ΠΩΣ ΘΕΛΕΙ ΜΟΝΟ ΑΥΤΉ ΤΗΝ ΕΙΔΙΚΟΤΗΤΑ ΚΑΙ ΚΑΜΙΑ ΆΛΛΗ. ΔΕΝ ΘΈΛΕΙ ΑΛΛΕΣ ΕΙΔΟΚΟΤΗΤΕΣΟΠΩΣ ΔΙΟΙΚΗΣΗ ΚΑΙ ΕΙΠΕ ΘΑ ΤΟ ΣΚΕΥΤΕΙ ΚΑΙ ΘΑ ΚΑΛΕΣΕΙ ΕΚΕΙΝΗ
A40: 39 | B40: Δευτέρα, 25 Αυγούστου 2025 | C40: 15:26 μμ | D40: Τεχνικός Εφαρμογών Πληροφορικής | E40: ΚΩΝΣΤΑΝΤΙΝΟΣ ΦΡΑΓΚΑΚΗΣ | F40: olgabkr@yahoo.com | G40: 6976118072 | H40: E-mail | I40: ΤΟΝ ΚΑΛΕΣΑΜΕ, ΔΕΝ ΤΟ ΣΗΚΩΣΕ ΚΑΙ ΜΕΤΆ ΚΆΛΕΣΕ ΕΚΕΙΝΗ ΗΤΑΝ Η ΜΑΜΑ ΤΟΥ ΚΑΙ ΗΘΕΛΕ ΝΑ ΕΓΓΡΆΨΕΙ ΤΟΝ ΓΙΟ ΤΗΣ ΜΕΤΑ ΑΠΌ ΜΑΘΗΤΕΙΑ ΣΤΗΝ ΙΣΑΕΚ, ΑΛΛΆ ΕΜΕΙΣ ΔΕΝ ΕΧΟΥΜΕ ΤΡΙΤΟ ΕΞΑΜΗΝΟ ΚΑΙ ΔΕΝ ΜΠΟΡΟΥΜΕ
A41: 40 | B41: Πέμπτη, 28 Αυγούστου 2025 | C41: 15:26 μμ | D41: Εσωτερική Αρχιτεκτονική Διακόσμηση και Σχεδιασμός Αντικειμένων | E41: ΣΥΝΤΙΧΑΚΗ ΓΕΩΡΓΙΑ | F41: gewrgia199494@gmail.com | G41: 6943832793 | H41: Απο φίλο / γνωστό | I41: ΗΘΕΛΕ ΚΑΠΟΙΑ ΕΠΙΠΛΕΩΝ ΕΚΠΤΩΣΗ ΚΑΙ ΤΗΣ ΕΙΠΑ ΝΑ ΣΤΕΙΛΕΙ ΠΡΟΤΑΣΗ. ΚΑΙ ΝΑ ΤΟ ΔΟΥΜΕ ΚΑΙ ΝΑ ΔΟΥΜΕ ΚΑΙ ΘΑ ΚΑΛΕΣΕΙ ΑΠΌ ΔΕΥΤΕΡΑ ΘΕΛΕΙ ΑΠΟΓΕΥΜΑΤΙΝΟ ΡΑΝΤΕΒΟΥ ΜΕΤΑ ΤΙΣ 18:00
A42: 41 | B42: Παρασκεύη, 29 Αυγούστου 2025 | C42: 19:10 μμ | D42: Τεχνικός Λογισμικού Ηλεκτρονικών Υπολογιστών | E42: ΕΥΘΥΜΙΟΣ ΣΩΜΑΡΑΚΗΣ | F42: SOMMAKIS@GMAIL.COM | G42: 6995185688 | H42: Εφημερίδα | I42: ΤΟΝ ΚΑΛΕΣΑ ΚΑΙ ΖΗΤΟΥΣΕ ΠΛΗΡΟΦΟΡΙΕΣ ΓΙΑ ΔΙΔΑΚΤΡΑ, ΑΝ ΕΧΟΥΜΕ ΛΕΕΙ ΥΠΟΛΟΓΙΣΤΕΣ ΚΑΙ ΥΛΙΚΟ ΚΑΙ ΖΗΤΟΎΣΕ ΚΑΙ ΝΑ ΜΆΘΕΙ ΜΕΧΡΙ ΠΟΤΕ ΜΠΟΡΕΙ ΝΑ ΓΡΑΦΤΕΙ ΚΑΙ ΑΝ ΧΡΕΙΆΖΕΤΑΙ ΝΑ ΕΧΕΙ ΣΥΜΠΛΗΡΩΘΕΙ ΤΜΗΜΑ ΓΙΑ ΝΑ ΓΙΝΕΙ
A43: 42 | B43: Πέμπτη, 04 Σεπτεμβρίου 2025 | C43: 17:05 μμ | D43: Τεχνικός Μαγειρικής Τέχνης–Αρχιμάγειρας(CHEF) | E43: Αντώνης Δημήτρης Σολακάκης | F43: sl.anton95@gmail.com | G43: 6945958347 | H43: Ιστοσελίδα / Αναζήτηση | I43: ΤΟΝ ΚΑΛΕΣΑ 2 ΦΟΡΕΣ ΚΑΙ ΤΕΛΙΚΑ ΔΕΝ ΤΟ ΑΠΑΝΤΗΣΕ ΚΑΙ ΤΟΥ ΕΣΤΕΙΛΑ EMAIL
A44: 43 | B44: Σάββατο, 06 Σεπτεμβρίου 2025 | C44: 0.41666667 | D44: Εσωτερική Αρχιτεκτονική Διακόσμηση και Σχεδιασμός Αντικειμένων | E44: Eirini Maniou | F44: manios80@yqhoo.gr | G44: 6948537700 | H44: Απο φίλο / γνωστό | I44: ΤΗΝ ΚΑΛΕΣΑ ΚΑΙ ΚΛΕΙΣΑΜΕ ΡΑΝΤΕΒΟΥ ΓΙΑ ΤΗΝ ΕΠΟΜΕΝΗ ΜΕΡΑ ΤΟ ΜΕΣΗΜΕΡΙ
...

Sheet ΚΑΤΑΣΤΑΣΗ ΣΠΟΥΔΑ ΚΑΙ ΕΚΠΑΙΔ
A1: ΣΠΟΥΔΑΣΤΕΣ | H1: ΑΠΟΥΣΙΕΣ ΧΕΙΜΕΡΙΝΟΥ ΕΞΑΜΗΝΟΥ | S1: ΑΠΟΥΣΙΕΣ ΕΑΙΝΟΥ ΕΞΑΜΗΝΟΥ | AI1: ΕΚΠΑΙΔΕΥΤΕΣ
A2: Α/Α | B2: ΤΜΗΜΑ | C2: ΟΝΟΜΑ | D2: ΕΠΩΝΥΜΟ | E2: Αριθμός Μητρώου | F2: EMAIL | G2: ΤΕΛΕΦΩΝΟ | H2: ΦΥΣΙΚΑ ΠΕΤΡΩΜΑΤΑ | I2: ΠΑΛΑΙΟΤΕΡΟΙ ΠΟΛΙΤΙΣΜΟΙ ΚΑΙ ΤΕΧΝΗ | J2: ΓΡΑΜΜΙΚΟ ΣΧΕΔΙΟ | K2: ΕΛΕΥΘΕΡΟ ΚΑΙ ΒΑΣΙΚΟ ΣΧΕΔΙΟ | L2: ΧΡΩΜΑ ΚΑΙ ΔΙΑΚΟΣΜΗΤΙΚΕΣ ΕΦΑΡΜΟΓΕΣ | M2: ΠΡΑΚΤΙΚΗ ΕΦΑΡΜΟΓΗ σε χώρο βιτρίνας | S2: ΑΝΑΓΕΝΝΗΣΗ ΚΑΙ ΝΕΟΤΕΡΗ ΤΕΧΝΗ | T2: ΠΑΡΑΓΩΓΑ ΥΛΙΚΑ | U2: ΜΕΘΟΔΟΛΟΓΙΑ ΜΕΛΕΤΗΣ ΔΙΑΚΟΣΜΗΣΗΣ | V2: ΔΙΣΔΙΑΣΤΑΤΗ ΨΗΦΙΑΚΗ ΣΧΕΔΙΑΣΗ | W2: ΤΡΙΣΔΙΑΣΤΑΤΗ ΔΙΑΚΟΣΜΗΤΙΚΗ ΑΠΕΙΚΟΝΙΣΗ | X2: ΠΡΑΚΤΙΚΗ ΕΦΑΡΜΟΓΗ ΣΕ ΧΩΡΟΥΣ ΚΑΤΟΙΚΙΑΣ | Y2: ΔΟΜΙΚΑ ΣΤΟΙΧΕΙΑ ΕΣΩΤΕΡΙΚΩΝ ΧΩΡΩΝ | AI2: Α/Α | AJ2: ΕΠΙΘΕΤΟ | AK2: ΟΝΟΜΑ | AL2: ΚΙΝΗΤΟ | AM2: EMAIL | AN2: ΤΜΗΜΑ | AO2: ΤΙΜΟΛΟΓΙΟ VS ΣΥΜΒΑΣΗ | AP2: ΩΡΕΣ ΠΟΥ ΔΕΝ ΕΓΙΝΑΝ ΑΝΑΠΛΗΡΩΣΗ | AQ2: ΩΡΕΣ ΟΚΤΩΜΒΡΙΟΥ | AR2: ΩΡΕΣ ΝΟΕΜΒΡΙΟΥ | AS2: ΩΡΕΣ ΔΕΚΕΜΒΡΙΟΥ | AT2: ΩΡΕΣ ΙΑΝΟΥΑΡΙΟΥ | AU2: ΩΡΕΣ ΦΕΒΡΟΥΑΡΙΟΥ | AV2: ΛΟΓΑΡΙΑΣΜΟΙ IBAN | AW2: ΩΡΕΣ ΦΕΒΡΟΥΑΡΙΟΥ | AX2: ΩΡΕΣ ΜΑΡΤΙΟΥ | AY2: ΩΡΕΣ ΑΠΡΙΛΙΟΥ | AZ2: ΩΡΕΣ ΜΑΙΟΥ | BA2: ΩΡΕΣ ΙΟΥΝΙΟΥ
A3: 1 | B3: ΕΣΩΤΕΡΙΚΗ ΑΡΧΙΤΕΚΤΟΝΙΚΗ ΔΙΑΚΟΣΜΗΣΗ ΚΑΙ ΣΧΕΔΙΑΣΜΟΣ ΑΝΤΙΚΕΙΜΕΝΩΝ (1ο ΕΤΟΣ) | H3: 5 | I3: 5 | J3: 9 | K3: 9 | L3: 9 | M3: 9 | S3: 6 | T3: 6 | U3: 6 | V3: 12 | W3: 9 | X3: 12 | Y3: 9 | AI3: 1 | AJ3: ΑΠΛΑΔΑ | AK3: ΣΟΦΙΑ - ΧΑΡΑ | AL3: 6949455771 | AM3: sofiacharapple@gmail.com | AN3: Τεχνικός Αρτοποιίας – Ζαχαροπλαστικής | AO3: ΣΥΜΒΑΣΗ | AV3: Πειραιώς: GR8201714330006433139066923
A4: 2 | B4: ΕΣΩΤΕΡΙΚΗ ΑΡΧΙΤΕΚΤΟΝΙΚΗ ΔΙΑΚΟΣΜΗΣΗ ΚΑΙ ΣΧΕΔΙΑΣΜΟΣ ΑΝΤΙΚΕΙΜΕΝΩΝ (1ο ΕΤΟΣ) | H4: 5 | I4: 5 | J4: 9 | K4: 9 | L4: 9 | M4: 9 | S4: 6 | T4: 6 | U4: 6 | V4: 12 | W4: 9 | X4: 12 | Y4: 9 | AI4: 2 | AJ4: ΚΟΥΝΔΟΥΡΑΚΗ | AK4: ΗΛΕΚΤΡΑ | AL4: 6984501017 | AM4: koundouraki@katartisi.gr | AN4: Στέλεχος Διοίκησης και Οικονομίας | AO4: ΣΥΜΒΑΣΗ | AV4: υπάρχουν τα στοιχεία τραπεζικού λογαριασμού
A5: 3 | B5: ΕΣΩΤΕΡΙΚΗ ΑΡΧΙΤΕΚΤΟΝΙΚΗ ΔΙΑΚΟΣΜΗΣΗ ΚΑΙ ΣΧΕΔΙΑΣΜΟΣ ΑΝΤΙΚΕΙΜΕΝΩΝ (1ο ΕΤΟΣ) | H5: 5 | I5: 5 | J5: 9 | K5: 9 | L5: 9 | M5: 9 | S5: 6 | T5: 6 | U5: 6 | V5: 12 | W5: 9 | X5: 12 | Y5: 9 | AI5: 3 | AJ5: ΚΥΡΛΑΚΗΣ | AK5: ΜΑΡΙΟΣ | AL5: 6955515575 | AM5: kirlakismarios@gmail.com | AN5: Τεχνικός Μαγερικής Τέχνης | AO5: ΣΥΜΒΑΣΗ | AV5: είναι ο ίδιος λογαρισμός
A6: 4 | B6: ΕΣΩΤΕΡΙΚΗ ΑΡΧΙΤΕΚΤΟΝΙΚΗ ΔΙΑΚΟΣΜΗΣΗ ΚΑΙ ΣΧΕΔΙΑΣΜΟΣ ΑΝΤΙΚΕΙΜΕΝΩΝ (1ο ΕΤΟΣ) | H6: 5 | I6: 5 | J6: 9 | K6: 9 | L6: 9 | M6: 9 | S6: 6 | T6: 6 | U6: 6 | V6: 12 | W6: 9 | X6: 12 | Y6: 9 | AI6: 4 | AJ6: ΜΑΡΚΑΚΗ ΤΡΥΠΑΚΗ | AK6: ΠΕΛΑΓΙΑ | AL6: 6948486899 | AM6: ptrypaki@yahoo.gr | AN6: Στέλεχος Υπηρεσιών Αερομεταφοράς | AO6: ΣΥΜΒΑΣΗ | AV6: ΕΘΝΙΚΗ: GR6701108050000080560371439
A7: 5 | B7: ΕΣΩΤΕΡΙΚΗ ΑΡΧΙΤΕΚΤΟΝΙΚΗ ΔΙΑΚΟΣΜΗΣΗ ΚΑΙ ΣΧΕΔΙΑΣΜΟΣ ΑΝΤΙΚΕΙΜΕΝΩΝ (1ο ΕΤΟΣ) | H7: 5 | I7: 5 | J7: 9 | K7: 9 | L7: 9 | M7: 9 | S7: 6 | T7: 6 | U7: 6 | V7: 12 | W7: 9 | X7: 12 | Y7: 9 | AI7: 5 | AJ7: ΜΠΙΤΖΟΥ | AK7: ΘΕΟΔΟΣΙΑ | AL7: 6944632864 και 2811391656 | AM7: thbitzou@gmail.com | AN7: Εσωτερική Αρχιτεκτονική Διακόσμηση και Σχεδιασμός Αντικειμένων | AO7: ΣΥΜΒΑΣΗ | AV7: ΠΕΙΡΑΙΩΣ: GR8601727550005755015924445
A8: 6 | B8: ΕΣΩΤΕΡΙΚΗ ΑΡΧΙΤΕΚΤΟΝΙΚΗ ΔΙΑΚΟΣΜΗΣΗ ΚΑΙ ΣΧΕΔΙΑΣΜΟΣ ΑΝΤΙΚΕΙΜΕΝΩΝ (1ο ΕΤΟΣ) | H8: 5 | I8: 5 | J8: 9 | K8: 9 | L8: 9 | M8: 9 | S8: 6 | T8: 6 | U8: 6 | V8: 12 | W8: 9 | X8: 12 | Y8: 9 | AI8: 6 | AJ8: ΝΕΟΝΑΚΗ | AK8: ΜΑΡΙΝΑ | AL8: 6972089035 | AM8: neonakimar@yahoo.gr | AN8: Τεχνικός Αρτοποιίας – Ζαχαροπλαστικής | AO8: ΣΥΜΒΑΣΗ | AV8: Eurobank: GR4902601340000000200749466
A9: 7 | B9: ΕΣΩΤΕΡΙΚΗ ΑΡΧΙΤΕΚΤΟΝΙΚΗ ΔΙΑΚΟΣΜΗΣΗ ΚΑΙ ΣΧΕΔΙΑΣΜΟΣ ΑΝΤΙΚΕΙΜΕΝΩΝ (1ο ΕΤΟΣ) | H9: 5 | I9: 5 | J9: 9 | K9: 9 | L9: 9 | M9: 9 | S9: 6 | T9: 6 | U9: 6 | V9: 12 | W9: 9 | X9: 12 | Y9: 9 | AI9: 7 | AJ9: ΠΑΠΑΔΟΜΑΝΩΛΑΚΗΣ | AK9: ΔΗΜΗΤΡΗΣ | AL9: 6945452188 | AM9: dpapadomanolakis@uniwa.gr | AN9: Στέλεχος Διοίκησης και Οικονομίας | AO9: ΣΥΜΒΑΣΗ | AV9: EUROBANK: GR4902600020000630101333443
A10: 8 | B10: ΕΣΩΤΕΡΙΚΗ ΑΡΧΙΤΕΚΤΟΝΙΚΗ ΔΙΑΚΟΣΜΗΣΗ ΚΑΙ ΣΧΕΔΙΑΣΜΟΣ ΑΝΤΙΚΕΙΜΕΝΩΝ (1ο ΕΤΟΣ) | H10: 5 | I10: 5 | J10: 9 | K10: 9 | L10: 9 | M10: 9 | S10: 6 | T10: 6 | U10: 6 | V10: 12 | W10: 9 | X10: 12 | Y10: 9 | AI10: 8 | AJ10: ΡΕΠΑΝΑΚΗ | AK10: ΔΕΣΠΟΙΝΑ | AL10: 6937037501 | AM10: repdebbie@gmail.com | AN10: Στέλεχος Υπηρεσιών Αερομεταφοράς | AO10: ΣΥΜΒΑΣΗ | AV10: EUROBANK GR 2002603300000130201705162
A11: 9 | B11: ΕΣΩΤΕΡΙΚΗ ΑΡΧΙΤΕΚΤΟΝΙΚΗ ΔΙΑΚΟΣΜΗΣΗ ΚΑΙ ΣΧΕΔΙΑΣΜΟΣ ΑΝΤΙΚΕΙΜΕΝΩΝ (1ο ΕΤΟΣ) | H11: 5 | I11: 5 | J11: 9 | K11: 9 | L11: 9 | M11: 9 | S11: 6 | T11: 6 | U11: 6 | V11: 12 | W11: 9 | X11: 12 | Y11: 9 | AI11: 9 | AJ11: ΣΑΜΟΛΗ | AK11: ΣΤΑΥΡΟΥΛΑ | AL11: 6939160280 | AM11: samolistavroula19@gmail.com | AN11: Στέλεχος Υπηρεσιών Αερομεταφοράς | AO11: ΣΥΜΒΑΣΗ | AV11: Τράπεζα Πειραιώς GR0401727510 005751063714325
A12: 10 | B12: ΕΣΩΤΕΡΙΚΗ ΑΡΧΙΤΕΚΤΟΝΙΚΗ ΔΙΑΚΟΣΜΗΣΗ ΚΑΙ ΣΧΕΔΙΑΣΜΟΣ ΑΝΤΙΚΕΙΜΕΝΩΝ (1ο ΕΤΟΣ) | H12: 5 | I12: 5 | J12: 9 | K12: 9 | L12: 9 | M12: 9 | S12: 6 | T12: 6 | U12: 6 | V12: 12 | W12: 9 | X12: 12 | Y12: 9 | AI12: 10 | AJ12: ΧΑΝΙΩΤΑΚΗΣ | AK12: ΧΑΡΑΛΑΜΠΟΣ | AL12: 6977586273 | AM12: babis.chaniotakis@gmail.com | AN12: Τεχνικός Αρτοποιίας – Ζαχαροπλαστικής | AO12: ΣΥΜΒΑΣΗ | AV12: Eurobank: GR5002604030000530200115581
AI13: 11 | AJ13: ΑΝΑΓΝΩΣΤΑΚΗ | AK13: ΝΙΚΗ | AL13: 6983756076 | AM13: ni.anagnostaki@gmail.com | AN13: ΔΙΚΑΙΟ | AO13: ΤΙΜΟΛΟΓΙΟ | AV13: ΠΕΙΡΑΙΩΣ GR9301722330005233087759281 ΕΘΝΙΚΗ GR1401107550000075501242814
A14: Α/Α | B14: ΤΜΗΜΑ | C14: ΟΝΟΜΑ | D14: ΕΠΩΝΥΜΟ | E14: Αριθμός Μητρώου | F14: EMAIL | G14: ΤΕΛΕΦΩΝΟ | H14: ΤΕΧΝΗΤΑ ΥΛΙΚΑ | I14: ΣΥΓΧΡΟΝΗ ΚΑΙ ΕΛΛΗΝΙΚΗ ΤΕΧΝΗ | J14: ΤΡΙΣΔΙΑΣΤΑΤΗ ΨΗΦΙΑΚΗ ΣΧΕΔΙΑΣΗ | K14: ΚΑΤΑΣΚΕΥΑΣΤΙΚΟ ΣΧΕΔΙΟ ΕΣΩΤΕΡΙΚΩΝ ΧΩΡΩΝ | L14: ΔΙΑΚΟΣΜΗΤΙΚΕΣ ΕΦΑΡΜΟΓΕΣ ΧΡΗΣΤΙΚΩΝ ΑΝΤΙΚΕΙΜΕΝΩΝ | M14: ΠΡΑΚΤΙΚΗ ΕΦΑΡΜΟΓΗ σε χώρους εργασίας | S14: ΟΡΓΑΝΩΣΗ ΕΡΓΑΣΙΩΝ ΕΡΓΟΥ | T14: ΨΗΦΙΑΚΟΣ ΦΩΤΟΡΕΑΛΙΣΜΟΣ | U14: ΔΙΑΚΟΣΜΗΤΙΚΟ ΣΧΕΔΙΟ | V14: ΠΡΑΚΤΙΚΗ ΕΦΑΡΜΟΓΗ ΣΕ ΧΩΡΟΥΣ ΦΙΛΟΞΕΝΙΑΣ | W14: ΔΙΑΚΟΣΜΗΤΙΚΕΣ ΜΕΤΑΒΛΗΤΕΣ ΕΦΑΡΜΟΓΕΣ | AI14: 12 | AJ14: ΒΟΓΙΑΤΖΗΣ | AK14: ΔΙΟΝΥΣΗΣ | AL14: 6946076210 & 2810236060 | AM14: nioniosvog@hotmail.com | AN14: Τεχνικός Αρτοποιίας – Ζαχαροπλαστικής | AO14: ΤΙΜΟΛΟΓΙΟ | AV14: είναι ο ίδιος λογαρισμός
A15: 1 | B15: ΕΣΩΤΕΡΙΚΗ ΑΡΧΙΤΕΚΤΟΝΙΚΗ ΔΙΑΚΟΣΜΗΣΗ ΚΑΙ ΣΧΕΔΙΑΣΜΟΣ ΑΝΤΙΚΕΙΜΕΝΩΝ (2ο ΕΤΟΣ) | C15: ΑΝΤΩΝΗΣ | D15: ΠΑΠΑΔΟΠΟΥΛΟΣ | E15: 59 | F15: iwona55@windowslive.com, antonis232123@outlook.com.gr | G15: 6951957501 | H15: 5 | I15: 5 | J15: 9 | K15: 7 | L15: 11 | M15: 9 | S15: 6 | T15: 12 | U15: 12 | V15: 15 | W15: 15 | AI15: 13 | AJ15: ΚΟΥΜΑΚΗΣ | AK15: ΚΩΝΣΤΑΝΤΙΝΟΣ | AL15: 6974120129, 2810334407 | AM15: info@zaxaroplasteiokoumakis.gr | AN15: Τεχνικός Αρτοποιίας – Ζαχαροπλαστικής | AO15: ΤΙΜΟΛΟΓΙΟ | AV15: ΈΧΕΙ ΤΟΝ ΠΕΡΣΙΝΟ ΕΙΠΕ
A16: 2 | B16: ΕΣΩΤΕΡΙΚΗ ΑΡΧΙΤΕΚΤΟΝΙΚΗ ΔΙΑΚΟΣΜΗΣΗ ΚΑΙ ΣΧΕΔΙΑΣΜΟΣ ΑΝΤΙΚΕΙΜΕΝΩΝ (2ο ΕΤΟΣ) | C16: ΝΙΚΟΛ | D16: ΑΝΑΣΤΑΣΙΑΔΗ | E16: 60 | F16: anasta.nicole@gmail.com | G16: 6993230075 | H16: 5 | I16: 5 | J16: 9 | K16: 7 | L16: 11 | M16: 9 | S16: 6 | T16: 12 | U16: 12 | V16: 15 | W16: 15 | AI16: 14 | AJ16: ΛΥΡΑΤΖΑΚΗ | AK16: ΕΛΕΝΗ | AL16: 6955951660 | AM16: elenhlyratzakh@gmail.com | AN16: Εσωτερική Αρχιτεκτονική Διακόσμηση και Σχεδιασμός Αντικειμένων | AO16: ΤΙΜΟΛΟΓΙΟ | AV16: EUROBANK: GR9002601340000010201479574
A17: 3 | B17: ΕΣΩΤΕΡΙΚΗ ΑΡΧΙΤΕΚΤΟΝΙΚΗ ΔΙΑΚΟΣΜΗΣΗ ΚΑΙ ΣΧΕΔΙΑΣΜΟΣ ΑΝΤΙΚΕΙΜΕΝΩΝ (2ο ΕΤΟΣ) | C17: ΓΙΑΝΝΗΣ | D17: ΚΟΥΤΣΟΓΙΑΝΝΑΚΗΣ | E17: 58 | F17: gianneskoutsogiannakes@gmail.com | G17: 6988403440 | H17: 5 | I17: 5 | J17: 9 | K17: 7 | L17: 11 | M17: 9 | S17: 6 | T17: 12 | U17: 12 | V17: 15 | W17: 15 | AI17: 15 | AJ17: ΛΥΡΑΤΖΑΚΗΣ | AK17: ΑΛΕΞΑΝΔΡΟΣ | AL17: 6979641896 | AM17: alyratzakis@gmail.com | AN17: Εσωτερική Αρχιτεκτονική Διακόσμηση και Σχεδιασμός Αντικειμένων | AO17: ΤΙΜΟΛΟΓΙΟ | AV17: EUROBANK: GR9002601340000010201479574
A18: 4 | B18: ΕΣΩΤΕΡΙΚΗ ΑΡΧΙΤΕΚΤΟΝΙΚΗ ΔΙΑΚΟΣΜΗΣΗ ΚΑΙ ΣΧΕΔΙΑΣΜΟΣ ΑΝΤΙΚΕΙΜΕΝΩΝ (2ο ΕΤΟΣ) | C18: ΕΙΡΗΝΗ | D18: ΠΕΡΗΦΑΝΟΥ | E18: 73 | F18: eiriniperif@gmail.com | G18: 6984495182 | H18: 5 | I18: 5 | J18: 9 | K18: 7 | L18: 11 | M18: 9 | S18: 6 | T18: 12 | U18: 12 | V18: 15 | W18: 15 | AI18: 16 | AJ18: ΠΑΠΑΦΡΑΓΚΑΚΗ | AK18: ΦΩΤΕΙΝΗ | AL18: 6989676442 | AM18: fpapafragaki@gmail.com | AN18: ΑΓΓΛΙΚΑ | AO18: ΤΙΜΟΛΟΓΙΟ | AV18: ΠΑΓΚΡΗΤΙΑ GR7801600150000000150992851
A19: 5 | B19: ΕΣΩΤΕΡΙΚΗ ΑΡΧΙΤΕΚΤΟΝΙΚΗ ΔΙΑΚΟΣΜΗΣΗ ΚΑΙ ΣΧΕΔΙΑΣΜΟΣ ΑΝΤΙΚΕΙΜΕΝΩΝ (2ο ΕΤΟΣ) | C19: ΕΥΑ | D19: ΧΑΙΝΑΚΗ | E19: 75 | F19: ehainaki@gmail.com | G19: 6983006334 | H19: 5 | I19: 5 | J19: 9 | K19: 7 | L19: 11 | M19: 9 | S19: 6 | T19: 12 | U19: 12 | V19: 15 | W19: 15 | AI19: 17 | AJ19: ΣΑΒΑ | AK19: ΜΙΚΑΕΛΑ | AL19: 6946047218 | AM19: mikasava96@gmail.com | AN19: ΓΑΛΛΙΚΑ | AO19: ΤΙΜΟΛΟΓΙΟ | AV19: είναι ο ίδιος λογαρισμός
AI20: 18 | AJ20: ΣΚΟΡΔΟΥ | AK20: ΕΛΕΝΗ | AL20: 6973739823 | AM20: elenskordou@gmail.com | AN20: Εσωτερική Αρχιτεκτονική Διακόσμηση και Σχεδιασμός Αντικειμένων | AO20: ΤΙΜΟΛΟΓΙΟ | AV20: ALPHA BANK: GR2901407750775002002022156
A21: Α/Α | B21: ΤΜΗΜΑ | C21: ΟΝΟΜΑ | D21: ΕΠΩΝΥΜΟ | E21: Αριθμός Μητρώου | F21: EMAIL | G21: ΤΕΛΕΦΩΝΟ | H21: ΕΙΣΑΓΩΓΗ ΣΤΗ ΓΕΝΙΚΗ ΛΟΓΙΣΤΙΚΗ | I21: ΑΣΤΙΚΟ ΔΙΚΑΙΟ | J21: ΕΙΣΑΓΩΓΗ ΣΤΑ ΟΙΚΟΝΟΜΙΚΑ ΜΑΘΗΜΑΤΙΚΑ | K21: ΕΙΣΑΓΩΓΗ ΣΤΗΝ ΣΤΑΤΙΣΤΙΚΗ | L21: ΕΙΣΑΓΩΓΗ ΣΤΗ ΔΙΟΙΚΗΣΗ ΕΠΙΧΕΙΡΗΣΕΩΝ | M21: ΕΠΑΓΓΕΛΜΑΤΙΚΕΣ ΔΕΞΙΟΤΗΤΕΣ ΜΕ ΤΗ ΧΡΗΣΗ ΛΟΓΙΣΤΙΚΩΝ ΦΥΛΛΩΝ | S21: ΕΜΠΟΡΙΚΟ ΔΙΚΑΙΟ | T21: ΕΙΔΙΚΑ ΘΕΜΑΤΑ ΔΙΟΙΚΗΣΗΣ ΕΠΙΧΕΙΡΗΣΕΩΝ | U21: ΠΡΑΚΤΙΚΗ ΕΦΑΡΜΟΓΗ ΣΤΗΝ ΕΙΔΙΚΟΤΗΤΑ | V21: ΕΙΔΙΚΑ ΘΕΜΑΤΑ ΟΙΚΟΝΟΜΙΚΩΝ ΜΑΘΗΜΑΤΙΚΩΝ | W21: ΕΙΔΙΚΑ ΘΕΜΑΤΑ ΣΤΑΤΙΣΤΙΚΗΣ | X21: ΟΙΚΟΝΟΜΙΚΗ ΤΩΝ ΕΠΙΧΕΙΡΗΣΕΩΝ | Y21: ΕΙΔΙΚΑ ΘΕΜΑΤΑ ΓΕΝΙΚΗΣ ΛΟΓΙΣΤΙΚΗΣ | Z21: ΕΠΙΧΕΙΡΙΣΙΑΚΕΣ ΕΠΙΚΟΙΝΩΝΙΕΣ | AI21: 19 | AJ21: ΤΣΑΚΙΡΕΛΗΣ | AK21: ΙΩΑΝΝΗΣ | AL21: 6936771591 | AM21: tsakirelis@gmail.com | AN21: Εσωτερική Αρχιτεκτονική Διακόσμηση και Σχεδιασμός Αντικειμένων | AO21: ΤΙΜΟΛΟΓΙΟ | AV21: EUROBANK: IBAN GR0302601670000640200710192
A22: 1 | B22: ΣΤΕΛΕΧΟΣ ΔΙΟΙΚΗΣΗΣ ΚΑΙ ΟΙΚΟΝΟΜΙΑΣ (1ο ΕΤΟΣ) | H22: 9 | I22: 5 | J22: 5 | K22: 5 | L22: 5 | M22: 7 | S22: 9 | T22: 6 | U22: 9 | V22: 6 | W22: 6 | X22: 6 | Y22: 12 | Z22: 6 | AI22: 20 | AJ22: ΦΥΣΑΡΑΚΗΣ | AK22: ΔΗΜΗΤΡΗΣ | AL22: 6976147069 | AM22: dfisarakis@gmail.com | AN22: Τεχνικός Αρτοποιίας – Ζαχαροπλαστικής | AO22: ΤΙΜΟΛΟΓΙΟ | AV22: ΕΘΝΙΚΗ GR8701107550000075501929618
A23: 2 | B23: ΣΤΕΛΕΧΟΣ ΔΙΟΙΚΗΣΗΣ ΚΑΙ ΟΙΚΟΝΟΜΙΑΣ (1ο ΕΤΟΣ) | H23: 9 | I23: 5 | J23: 5 | K23: 5 | L23: 5 | M23: 7 | S23: 9 | T23: 6 | U23: 9 | V23: 6 | W23: 6 | X23: 6 | Y23: 12 | Z23: 6 | AI23: 21 | AJ23: ΛΥΡΑΤΖΑΚΗ | AK23: ΕΛΕΝΗ | AL23: 6955951660 | AM23: elenhlyratzakh@gmail.com | AN23: Εσωτερική Αρχιτεκτονική Διακόσμηση και Σχεδιασμός Αντικειμένων | AO23: ΤΙΜΟΛΟΓΙΟ | AV23: EUROBANK: GR9002601340000010201479574
A24: 3 | B24: ΣΤΕΛΕΧΟΣ ΔΙΟΙΚΗΣΗΣ ΚΑΙ ΟΙΚΟΝΟΜΙΑΣ (1ο ΕΤΟΣ) | H24: 9 | I24: 5 | J24: 5 | K24: 5 | L24: 5 | M24: 7 | S24: 9 | T24: 6 | U24: 9 | V24: 6 | W24: 6 | X24: 6 | Y24: 12 | Z24: 6 | AI24: 22 | AJ24: ΛΥΡΑΤΖΑΚΗΣ | AK24: ΑΛΕΞΑΝΔΡΟΣ | AL24: 6979641896 | AM24: alyratzakis@gmail.com | AN24: Εσωτερική Αρχιτεκτονική Διακόσμηση και Σχεδιασμός Αντικειμένων | AO24: ΤΙΜΟΛΟΓΙΟ | AV24: EUROBANK: GR9002601340000010201479574
A25: 4 | B25: ΣΤΕΛΕΧΟΣ ΔΙΟΙΚΗΣΗΣ ΚΑΙ ΟΙΚΟΝΟΜΙΑΣ (1ο ΕΤΟΣ) | H25: 9 | I25: 5 | J25: 5 | K25: 5 | L25: 5 | M25: 7 | S25: 9 | T25: 6 | U25: 9 | V25: 6 | W25: 6 | X25: 6 | Y25: 12 | Z25: 6 | AI25: 23 | AJ25: ΠΑΠΑΦΡΑΓΚΑΚΗ | AK25: ΦΩΤΕΙΝΗ | AL25: 6989676442 | AM25: fpapafragaki@gmail.com | AN25: ΑΓΓΛΙΚΑ | AO25: ΤΙΜΟΛΟΓΙΟ | AV25: ΠΑΓΚΡΗΤΙΑ GR7801600150000000150992851
A26: 5 | B26: ΣΤΕΛΕΧΟΣ ΔΙΟΙΚΗΣΗΣ ΚΑΙ ΟΙΚΟΝΟΜΙΑΣ (1ο ΕΤΟΣ) | H26: 9 | I26: 5 | J26: 5 | K26: 5 | L26: 5 | M26: 7 | S26: 9 | T26: 6 | U26: 9 | V26: 6 | W26: 6 | X26: 6 | Y26: 12 | Z26: 6 | AI26: 24 | AJ26: ΣΑΒΑ | AK26: ΜΙΚΑΕΛΑ | AL26: 6946047218 | AM26: mikasava96@gmail.com | AN26: ΓΑΛΛΙΚΑ | AO26: ΤΙΜΟΛΟΓΙΟ | AV26: είναι ο ίδιος λογαρισμός
A27: 6 | B27: ΣΤΕΛΕΧΟΣ ΔΙΟΙΚΗΣΗΣ ΚΑΙ ΟΙΚΟΝΟΜΙΑΣ (1ο ΕΤΟΣ) | H27: 9 | I27: 5 | J27: 5 | K27: 5 | L27: 5 | M27: 7 | S27: 9 | T27: 6 | U27: 9 | V27: 6 | W27: 6 | X27: 6 | Y27: 12 | Z27: 6 | AI27: 25 | AJ27: ΣΚΟΡΔΟΥ | AK27: ΕΛΕΝΗ | AL27: 6973739823 | AM27: elenskordou@gmail.com | AN27: Εσωτερική Αρχιτεκτονική Διακόσμηση και Σχεδιασμός Αντικειμένων | AO27: ΤΙΜΟΛΟΓΙΟ | AV27: ALPHA BANK: GR2901407750775002002022156
A28: 6 | B28: ΣΤΕΛΕΧΟΣ ΔΙΟΙΚΗΣΗΣ ΚΑΙ ΟΙΚΟΝΟΜΙΑΣ (1ο ΕΤΟΣ) | H28: 9 | I28: 5 | J28: 5 | K28: 5 | L28: 5 | M28: 7 | S28: 9 | T28: 6 | U28: 9 | V28: 6 | W28: 6 | X28: 6 | Y28: 12 | Z28: 6 | AI28: 26 | AJ28: ΤΣΑΚΙΡΕΛΗΣ | AK28: ΙΩΑΝΝΗΣ | AL28: 6936771591 | AM28: tsakirelis@gmail.com | AN28: Εσωτερική Αρχιτεκτονική Διακόσμηση και Σχεδιασμός Αντικειμένων | AO28: ΤΙΜΟΛΟΓΙΟ | AV28: EUROBANK: IBAN GR0302601670000640200710192
A29: 7 | B29: ΣΤΕΛΕΧΟΣ ΔΙΟΙΚΗΣΗΣ ΚΑΙ ΟΙΚΟΝΟΜΙΑΣ (1ο ΕΤΟΣ) | H29: 9 | I29: 5 | J29: 5 | K29: 5 | L29: 5 | M29: 7 | S29: 9 | T29: 6 | U29: 9 | V29: 6 | W29: 6 | X29: 6 | Y29: 12 | Z29: 6 | AI29: 27 | AJ29: ΦΥΣΑΡΑΚΗΣ | AK29: ΔΗΜΗΤΡΗΣ | AL29: 6976147069 | AM29: dfisarakis@gmail.com | AN29: Τεχνικός Αρτοποιίας – Ζαχαροπλαστικής | AO29: ΤΙΜΟΛΟΓΙΟ | AV29: ΕΘΝΙΚΗ GR8701107550000075501929618
A30: 8 | B30: ΣΤΕΛΕΧΟΣ ΔΙΟΙΚΗΣΗΣ ΚΑΙ ΟΙΚΟΝΟΜΙΑΣ (1ο ΕΤΟΣ) | H30: 9 | I30: 5 | J30: 5 | K30: 5 | L30: 5 | M30: 7 | S30: 9 | T30: 6 | U30: 9 | V30: 6 | W30: 6 | X30: 6 | Y30: 12 | Z30: 6 | AJ30: ΦΥΓΕΤΑΚΗ | AK30: ΜΑΡΙΑ | AL30: 6955641311 | AM30: m.fygetaki@gmail.com | AN30: Στέλεχος Υπηρεσιών Αερομεταφοράς | AO30: ΣΥΜΒΑΣΗ | AV30: EUROBANK: GR5502602760000280101488588
A31: 10 | B31: ΣΤΕΛΕΧΟΣ ΔΙΟΙΚΗΣΗΣ ΚΑΙ ΟΙΚΟΝΟΜΙΑΣ (1ο ΕΤΟΣ) | H31: 9 | I31: 5 | J31: 5 | K31: 5 | L31: 5 | M31: 7 | S31: 9 | T31: 6 | U31: 9 | V31: 6 | W31: 6 | X31: 6 | Y31: 12 | Z31: 6 | AJ31: ΜΠΟΥΧΑΛΑΚΗΣ | AK31: ΕΜΜΑΝΟΥΗΛ | AL31: 6998108632 | AM31: manbouch@yahoo.com | AN31: ΑΓΓΛΙΚΑ | AO31: ΣΥΜΒΑΣΗ | AV31: ΔΕΝ ΕΓΡΑΨΕ ΤΡΑΠΕΖΑ ΜΑΛΛΟΝ ΕΊΝΑΙ EUROBANK: GR0902601340000070101663955
AJ32: ΤΖΑΝΑΚΗ | AK32: ΕΛΕΥΘΕΡΙΑ | AL32: 6973825235 | AM32: eleftheriatzanaki@gmail.com | AN32: Εσωτερική Αρχιτεκτονική Διακόσμηση και Σχεδιασμός Αντικειμένων | AO32: ΤΙΜΟΛΟΓΙΟ | AV32: Eurobank: GR3202606840000530103488326
A33: Α/Α | B33: ΤΜΗΜΑ | C33: ΟΝΟΜΑ | D33: ΕΠΩΝΥΜΟ | E33: Αριθμός Μητρώου | F33: EMAIL | G33: ΤΕΛΕΦΩΝΟ | H33: ΦΟΡΟΛΟΓΙΚΗ ΠΡΑΚΤΙΚΗ /ΦΟΡΟΛΟΓΙΚΕΣ ΕΦΑΡΜΟΓΕΣ | I33: ΛΟΓΙΣΤΙΚΗ ΕΤΑΙΡΕΙΩΝ | J33: ΜΗΧΑΝΟΓΡΑΦΗΜΕΝΗ ΛΟΓΙΣΤΙΚΗ | K33: ΛΟΓΙΣΤΙΚΗ ΚΟΣΤΟΥΣ | L33: ΔΗΜΟΣΙΕΣ ΣΧΕΣΕΙΣ ΚΑΙ ΕΠΙΚΟΙΝΩΝΙΑ | M33: ΕΠΕΞΕΡΓΑΣΙΑ ΚΕΙΜΕΝΟΥ (Η/Υ) | N33: ΠΡΑΚΤΙΚΗ ΕΦΑΡΜΟΓΗ ΣΤΗΝ ΕΙΔΙΚΟΤΗΤΑ | S33: ΕΠΙΧΕΙΡΗΜΑΤΙΚΟΤΗΤΑ & ΚΑΙΝΟΤΟΜΙΑ | T33: ΕΜΠΟΡΙΚΗ ΔΙΑΧΕΙΡΙΣΗ (WMS)-ΜΙΣΘΟΔΟΣΙΑ (PAYROLL) | U33: PROJECT MANAGEMENT | V33: ΧΡΗΜΑΤΟΟΙΚΟΝΟΜΙΚΗ ΔΙΟΙΚΗΣΗ – ΑΞΙΟΛΟΓΗΣΗ ΕΠΕΝΔΥΣΕΩΝ | W33: ΔΙΟΙΚΗΣΗ ΑΝΘΡΩΠΙΝΩΝ ΠΟΡΩΝ | X33: ΕΙΔΙΚΑ ΘΕΜΑΤΑ ΛΟΓΙΣΤΙΚΩΝ ΦΥΛΛΩΝ | Y33: ΠΡΑΚΤΙΚΗ ΕΦΑΡΜΟΓΗ ΣΤΗΝ ΕΙΔΙΚΟΤΗΤΑ | AJ33: ΧΑΤΖΗΝΤΕΒΕ | AK33: ΧΡΙΣΤΙΝΑ | AL33: 6940828922 | AM33: cchatzideve@gmail.com | AN33: Εσωτερική Αρχιτεκτονική Διακόσμηση και Σχεδιασμός Αντικειμένων | AO33: ΣΥΜΒΑΣΗ | AV33: είναι ο ίδιος λογαρισμός
A34: 1 | B34: ΣΤΕΛΕΧΟΣ ΔΙΟΙΚΗΣΗΣ ΚΑΙ ΟΙΚΟΝΟΜΙΑΣ (2ο ΕΤΟΣ) | C34: ΚΛΕΙΩ | D34: ΚΕΝΔΡΙΣΤΑΚΗ | E34: 81 | F34: kendristakek@gmail.com | G34: 6973585676 | AJ34: ΑΔΑΜΗΣ | AK34: ΓΕΩΡΓΙΟΣ | AL34: 6972600890 | AM34: georgeadamis1@gmail.com | AN34: Εσωτερική Αρχιτεκτονική Διακόσμηση και Σχεδιασμός Αντικειμένων | AO34: ΤΙΜΟΛΟΓΙΟ
A35: 2 | B35: ΣΤΕΛΕΧΟΣ ΔΙΟΙΚΗΣΗΣ ΚΑΙ ΟΙΚΟΝΟΜΙΑΣ (2ο ΕΤΟΣ) | C35: ΧΑΡΙΔΗΜΟΣ ΕΜΜΑΝΟΥΗΛ | D35: ΜΑΝΙΟΥΔΑΚΗΣ | E35: 82 | F35: charitosmanioudakes78@gmail.com | G35: 6971993662 | AJ35: ΖΑΧΑΡΙΑΔΑΚΗ | AK35: ΕΙΡΗΝΗ | AL35: 6944640433 | AM35: errikazaha@yahoo.gr | AN35: Εσωτερική Αρχιτεκτονική Διακόσμηση και Σχεδιασμός Αντικειμένων | AO35: ΣΥΜΒΑΣΗ
A36: 3 | B36: ΣΤΕΛΕΧΟΣ ΔΙΟΙΚΗΣΗΣ ΚΑΙ ΟΙΚΟΝΟΜΙΑΣ (2ο ΕΤΟΣ) | C36: ΠΑΥΛΙΝΑ | D36: ΜΩΥΣΑΚΗ | E36: 74 | F36: paulinamoysaki123@gmail.com | G36: 6985837967 | AJ36: ΚΑΛΟΓΕΡΑΚΗΣ | AK36: ΜΙΧΑΗΛ | AL36: 6971745097 | AM36: kalomich@outlook.com | AN36: ΔΙΚΑΙΟ | AO36: ΤΙΜΟΛΟΓΙΟ
A37: 4 | B37: ΣΤΕΛΕΧΟΣ ΔΙΟΙΚΗΣΗΣ ΚΑΙ ΟΙΚΟΝΟΜΙΑΣ (2ο ΕΤΟΣ) | C37: ΜΑΡΙΑ | D37: ΠΑΠΑΔΑΚΗ | E37: 72 | F37: papadakimar44@gmail.com | G37: 6944918511 | AJ37: ΚΟΝΙΔΑΚΗ | AK37: ΣΤΕΦΑΝΙΑ | AL37: 6979971391 | AM37: stephaniekonidaki@yahoo.gr | AN37: ΓΑΛΛΙΚΑ | AO37: ΣΥΜΒΑΣΗ
A38: 5 | B38: ΣΤΕΛΕΧΟΣ ΔΙΟΙΚΗΣΗΣ ΚΑΙ ΟΙΚΟΝΟΜΙΑΣ (2ο ΕΤΟΣ) | C38: ΕΜΜΑΝΟΥΕΛΑ | D38: ΡΙΖΟΥ | E38: 89 | F38: emmanuellarizou28@yahoo.com re.mmi24@yahoo.gr | G38: 6981865680 | AJ38: ΜΕΛΕΣΣΑΝΑΚΗΣ | AK38: ΔΗΜΗΤΡΙΟΣ | AL38: 6947560903 | AM38: dtsakal@yahoo.gr | AN38: =$AN$15 -> Τεχνικός Αρτοποιίας – Ζαχαροπλαστικής | AO38: ΣΥΜΒΑΣΗ
A39: 6 | B39: ΣΤΕΛΕΧΟΣ ΔΙΟΙΚΗΣΗΣ ΚΑΙ ΟΙΚΟΝΟΜΙΑΣ (2ο ΕΤΟΣ) | C39: ΧΡΙΣΤΙΝΑ | D39: ΤΡΙΓΩΝΗ | E39: 66 | F39: chtrigoni@gmail.com | G39: 6955298183 | AJ39: ΜΩΥΣΑΚΗΣ | AK39: ΙΩΑΝΝΗΣ | AL39: 6936003082 | AM39: moisakisgiannis@gmail.com | AN39: =$AN$15 -> Τεχνικός Αρτοποιίας – Ζαχαροπλαστικής | AO39: ΤΙΜΟΛΟΓΙΟ
A40: 7 | B40: ΣΤΕΛΕΧΟΣ ΔΙΟΙΚΗΣΗΣ ΚΑΙ ΟΙΚΟΝΟΜΙΑΣ (2ο ΕΤΟΣ) | C40: ΚΩΝΣΤΑΝΤΙΝΟΣ-ΜΑΡΙΟΣ | D40: ΤΣΙΚΑΝΔΥΛΑΚΗΣ | E40: 67 | F40: tsikandilakisn@gmail.com | G40: 6987401697 | AJ40: ΠΕΤΡΟΥΛΑΚΗ | AK40: ΑΝΤΩΝΙΑ | AL40: 6907054898 | AM40: toniapetroulaki2010@gmail.com | AN40: =$AN$5 -> Τεχνικός Μαγερικής Τέχνης | AO40: ΤΙΜΟΛΟΓΙΟ
...

Sheet ECLASS
A1: ECLASS ΣΥΝΔΕΣΜΟΣ | J1: ΣΠΟΥΔΑΣΤΕΣ | R1: ΕΚΠΑΙΔΕΥΤΕΣ | Z1: ΠΡΟΣΩΠΙΚΟ | AE1: ΜΑΘΗΜΑΤΑ ΧΕΙΜΕΡΙΝΟ ΕΞΑΜΗΝΟ | AJ1: ΜΑΘΗΜΑΤΑ ΕΑΡΙΝΟ ΕΞΑΜΗΝΟ | AO1: ΓΙΑ ΔΗΜΙΟΥΡΓΙΑ ΛΟΓΑΡΙΑΣΜΟΥ | AW1: ΟΔΗΓΙΕΣ ΓΙΑ ΣΥΝΔΕΣΗ
A2: https://eclass-isaek.katartisi.gr/ | J2: ΕΣΩΤΕΡΙΚΗ ΑΡΧΙΤΕΚΤΟΝΙΚΗ ΔΙΑΚΟΣΜΗΣΗ ΚΑΙ ΣΧΕΔΙΑΣΜΟΣ ΑΝΤΙΚΕΙΜΕΝΩΝ (1ο ΕΤΟΣ) | R2: ΠΙΝΑΚΑΣ ΜΕ ΛΟΓΑΡΙΣΜΟΥΣ ΣΤΟ ECLASS | Z2: first | AA2: last | AB2: email | AC2: username | AE2: ΕΣΩΤΕΡΙΚΗ ΑΡΧΙΤΕΚΤΟΝΙΚΗ ΔΙΑΚΟΣΜΗΣΗ ΚΑΙ ΣΧΕΔΙΑΣΜΟΣ ΑΝΤΙΚΕΙΜΕΝΩΝ | AJ2: ΕΣΩΤΕΡΙΚΗ ΑΡΧΙΤΕΚΤΟΝΙΚΗ ΔΙΑΚΟΣΜΗΣΗ ΚΑΙ ΣΧΕΔΙΑΣΜΟΣ ΑΝΤΙΚΕΙΜΕΝΩΝ | AO2: first | AP2: last | AQ2: email | AR2: id | AS2: phone | AT2: username | AU2: password | AW2: ΣΠΟΥΔΑΣΤΕΣ | BF2: ΕΚΠΑΙΔΕΥΤΕΣ
J3: first | K3: last | L3: email | M3: id | N3: phone | O3: username | P3: password | R3: first | S3: last | T3: email | U3: id | V3: phone | W3: username | X3: password | Z3: ΜΙΧΑΛΗΣ | AA3: ΚΑΘΑΡΑΚΗΣ | AB3: katharak@katartisi.gr | AC3: katharakis | AE3: ΜΑΘΗΜΑ | AF3: ΚΩΔΙΚΟΙ ΜΑΘΗΜΑΤΩΝ ΠΡΩΤΟ ΕΤΟΣ | AG3: ΜΑΘΗΜΑ | AH3: ΚΩΔΙΚΟΙ ΜΑΘΗΜΑΤΩΝ ΔΕΥΤΕΡΟ ΕΤΟΣ | AJ3: ΜΑΘΗΜΑ | AK3: ΚΩΔΙΚΟΙ ΜΑΘΗΜΑΤΩΝ ΠΡΩΤΟ ΕΤΟΣ | AL3: ΜΑΘΗΜΑ | AM3: ΚΩΔΙΚΟΙ ΜΑΘΗΜΑΤΩΝ ΔΕΥΤΕΡΟ ΕΤΟΣ | AW3: ΘΕΜΑ | AX3: 📘 Οδηγός πρώτης σύνδεσης στην πλατφόρμα eClass ΙΣΑΕΚ | BF3: ΘΕΜΑ | BG3: 📘 Οδηγός πρώτης σύνδεσης στην πλατφόρμα eClass ΙΣΑΕΚ
J4: ΑΝΤΩΝΗΣ | K4: ΠΑΠΑΔΟΠΟΥΛΟΣ | L4: iwona55@windowslive.com | M4: 59 | N4: 6951957501 | O4: papadopoulos | P4: 1234 | R4: ΘΕΟΔΟΣΙΑ | S4: ΜΠΙΤΖΟΥ | T4: thbitzou@gmail.com | U4: 1 | V4: 6944632864 | W4: bitzou | X4: 1234 | Z4: ΜΕΛΠΩ | AA4: ΜΙΧΕΛΑΚΗ | AB4: michelaki@katartisi.gr | AC4: michelaki | AE4: ΦΥΣΙΚΑ ΠΕΤΡΩΜΑΤΑ | AF4: ARCH101 | AG4: ΤΕΧΝΗΤΑ ΥΛΙΚΑ | AH4: ARCH107 | AJ4: ΠΑΡΑΓΩΓΑ ΥΛΙΚΑ | AK4: ARCH114 | AL4: ΟΡΓΑΝΩΣΗ ΕΡΓΟΥ | AM4: ARCH120 | AW4: ΚΥΡΙΟΣ ΚΕΙΜΕΝΟ | AX4: Αγαπητέ/ή εκπαιδευόμενε/η, Ο λογαριασμός σας για την εκπαιδευτική πλατφόρμα eClass έχει δημιουργηθεί. Μέσα από την πλατφόρμα θα μπορείτε: να έχετε πρόσβαση σε εκπαιδευτικό υλικό, να ενημερώνεστε για ανακοινώσεις και δραστηριότητες. (ΑΥΤΑ ΔΕΝ ΤΑ ΑΝΤΙΓΡΑΦΟΥΜΕ, ΤΑ ΚΡΑΤΑΜΕ ΚΑΙ ΤΑ ΕΧΟΥΜΕ ΩΣ ΜΠΟΥΣΟΥΛΑ ΠΩΣ ΑΝΤΙΓΡΑΦΟΥΜΕ ΤΑ ΠΑΝΩ ΚΑΙ ΤΑ ΚΑΤΩ ΑΠΟ ΑΥΤΑ ΓΙΑΤΙ ΑΥΤΑ ΤΑ ΕΧΕΙ ΩΣ USERNAME ΚΑΙ PASSWORD ΤΑ ΔΙΝΕΙ ΤΟ ECLASS)🔑 Στοιχεία λογαριασμού Όνομα χρήστη (username): [username] Συνθηματικό (password): [password] Διεύθυνση πλατφόρμας: https://eclass-isaek.katartisi.gr/ 📝 Βήματα πρώτης σύνδεσης Μεταβείτε στη διεύθυνση: https://eclass-isaek.katartisi.gr/. Εισάγετε το όνομα χρήστη και το συνθηματικό που σας δόθηκαν. Μόλις συνδεθείτε, κάντε αλλαγή κωδικού ώστε να βάλετε έναν νέο, πιο προσωπικό και εύκολο να θυμάστε. ℹ️ Χρήσιμες πληροφορίες Από την αρχική σελίδα του κάθε μαθήματος θα βρίσκετε σημειώσεις, υλικό, εργασίες και ανακοινώσεις. Ελέγχετε τακτικά την πλατφόρμα για ενημερώσεις από τον εκπαιδευτή. 📞 Υποστήριξη Αν αντιμετωπίσετε κάποιο πρόβλημα με τη σύνδεση ή τη χρήση της πλατφόρμας, μπορείτε να επικοινωνήσετε με: Μέλπω Μιχελάκη ή Μαρία Νικολοπούλου Τηλ.: 2810331580 Email: michelaki@katartisi.gr , nikolopoulou@katartisi.gr | BF4: ΚΥΡΙΟΣ ΚΕΙΜΕΝΟ | BG4: Αγαπητέ χρήστη, Ο λογαριασμός σας για την εκπαιδευτική πλατφόρμα eClass έχει δημιουργηθεί. Μέσα από την πλατφόρμα θα γίνεται ανάρτηση υλικού μαθημάτων, ανακοινώσεις και λοιπές εκπαιδευτικές δραστηριότητες. (ΑΥΤΑ ΔΕΝ ΤΑ ΑΝΤΙΓΡΑΦΟΥΜΕ, ΤΑ ΚΡΑΤΑΜΕ ΚΑΙ ΤΑ ΕΧΟΥΜΕ ΩΣ ΜΠΟΥΣΟΥΛΑ ΠΩΣ ΑΝΤΙΓΡΑΦΟΥΜΕ ΤΑ ΠΑΝΩ ΚΑΙ ΤΑ ΚΑΤΩ ΑΠΟ ΑΥΤΑ ΓΙΑΤΙ ΑΥΤΑ ΤΑ ΕΧΕΙ ΩΣ USERNAME ΚΑΙ PASSWORD ΤΑ ΔΙΝΕΙ ΤΟ ECLASS)🔑 Στοιχεία λογαριασμού Όνομα χρήστη (username): [username] Συνθηματικό (password): [password] Διεύθυνση πλατφόρμας: https://eclass-isaek.katartisi.gr/ 📝 Βήματα πρώτης σύνδεσης Μεταβείτε στη διεύθυνση: https://eclass-isaek.katartisi.gr/. Εισάγετε το όνομα χρήστη και το συνθηματικό που σας δόθηκαν. Μόλις συνδεθείτε, προχωρήστε σε αλλαγή κωδικού ώστε να ορίσετε έναν νέο, πιο προσωπικό και εύχρηστο. Ο νέος κωδικός θα πρέπει να είναι εύκολος για εσάς, αλλά δύσκολος να τον μαντέψει άλλος (π.χ. συνδυασμός γραμμάτων, αριθμών και συμβόλων). 📞 Υποστήριξη Αν αντιμετωπίσετε κάποιο πρόβλημα με τη σύνδεση ή τη χρήση της πλατφόρμας, μπορείτε να επικοινωνήσετε με: Μέλπω Μιχελάκη ή Μαρία Νικολοπούλου Τηλ.: 2810331580 Email: michelaki@katartisi.gr , nikolopoulou@katartisi.gr
J5: ΝΙΚΟΛ | K5: ΑΝΑΣΤΑΣΙΑΔΗ | L5: anasta.nicole@gmail.com | M5: 60 | N5: 6993230075 | O5: anastasiadi | P5: 1234 | R5: ΧΡΙΣΤΙΝΑ | S5: ΧΑΤΖΗΝΤΕΒΕ | T5: cchatzideve@gmail.com | U5: 2 | V5: 6940828922 | W5: chatzideve | X5: 1234 | Z5: ΜΑΡΙΑ | AA5: ΝΙΚΟΛΟΠΟΥΛΟΥ | AB5: nikolopoulou@katartisi.gr | AC5: nikolopoulou | AE5: ΠΑΛΑΙΟΤΕΡΟΙ ΠΟΛΙΤΙΣΜΟΙ ΚΑΙ ΤΕΧΝΗ | AF5: ARCH102 | AG5: ΣΥΓΧΡΟΝΗ ΚΑΙ ΕΛΛΗΝΙΚΗ ΤΕΧΝΗ | AH5: ARCH108 | AJ5: ΑΝΑΓΕΝΝΗΣΗ ΚΑΙ ΝΕΟΤΕΡΗ ΤΕΧΝΗ | AK5: ARCH115 | AL5: ΔΙΑΚΟΣΜΗΤΙΚΕΣ ΜΕΤΑΒΛΗΤΕΣ ΕΦΑΡΜΟΓΕΣ | AM5: ARCH121
J6: ΓΙΑΝΝΗΣ | K6: ΚΟΥΤΣΟΓΙΑΝΝΑΚΗΣ | L6: gianneskoutsogiannakes@gmail.com | M6: 58 | N6: 6988403440 | O6: Koutsogiannakis | P6: 1234 | R6: ΕΛΕΝΗ | S6: ΣΚΟΡΔΟΥ | T6: elenskordou@gmail.com | U6: 3 | V6: 6973739823 | W6: skordou | X6: 1234 | Z6: ΚΩΣΤΑΣ | AA6: ΤΣΙΚΑΛΑΣ | AB6: tsikalas@katartisi.gr | AC6: tsikalas | AE6: ΓΡΑΜΜΙΚΟ ΣΧΕΔΙΟ | AF6: ARCH103 | AG6: ΤΡΙΣΔΙΑΣΤΑΤΗ ΨΗΦΙΑΚΗ ΣΧΕΔΙΑΣΗ | AH6: ARCH109 | AJ6: ΜΕΘΟΔΟΛΟΓΙΑ ΜΕΛΕΤΗΣ ΔΙΑΚΟΣΜΗΣΗΣ | AK6: ARCH116 | AL6: ΨΗΦΙΑΚΟΣ ΦΩΤΟΡΕΑΛΙΣΜΟΣ | AM6: ARCH122
